Workbook

Sheet Roofs 1
H1: Exhibit B
V2: Explanatory Notes:
H3: RESERVE EXPENDITURES | P3: RefYr | U3: 1) | V3: 0.03 | W3: is the estimated future Inflation Rate for estimating Future Replacement Costs.
H4: for | P4: 2023 | U4: 2) | V4: Fiscal Year is beginning January 1 and ending December 31.
H5: ='Funding Plan'!G9 -> Association
B6: Line Item | D6: Estimated | J6: Estimated Year Last Replaced | L6: Life Analysis, Years | P6: Estimated Year of 1st Replacement | R6: 2024 Unit Cost | T6: 2024 Cost of Replacement | V6: Total Future Cost of Replacement | X6: 1 | Z6: 2 | AB6: 3 | AD6: 4 | AF6: 5 | AH6: 6 | AJ6: 7 | AL6: 8 | AN6: 9 | AP6: 10 | AR6: 11 | AT6: 12 | AV6: 13 | AX6: 14 | AZ6: 15
D7: Quantity | F7: Units | H7: Reserve Component Inventory | L7: Useful | N7: Remaining | X7: 2024 | Z7: =X7+1 -> 2025 | AA7: =Y7+1 -> 1 | AB7: =Z7+1 -> 2026 | AC7: =AA7+1 -> 2 | AD7: =AB7+1 -> 2027 | AE7: =AC7+1 -> 3 | AF7: =AD7+1 -> 2028 | AG7: =AE7+1 -> 4 | ... AZ7: =AX7+1 -> 2038
H9: Roofs
B11: 1 | D11: 1 | F11: x | H11: x | J11: 1 | K11: 23 | L11: 1 | N11: =P11-O11 -> -1999 | O11: =P4 -> 2023 | P11: =J11+K11 -> 24 | R11: 1 | T11: =D11*R11 -> 1 | V11: =SUM(X11:AZ11)+SUM(J61:AL61) -> 0 | X11: =IF(X$6=$N11,FV($V$3,$N11-1,,-$T11,0),0) -> 0 | Z11: =IF(Z$6=$N11,FV($V$3,$N11-1,,-$T11,0),0) -> 0 | AB11: =IF(AB$6=$N11,FV($V$3,$N11-1,,-$T11,0),0) -> 0 | AD11: =IF(AD$6=$N11,FV($V$3,$N11-1,,-$T11,0),0) -> 0 | AF11: =IF(AF$6=$N11,FV($V$3,$N11-1,,-$T11,0),0) -> 0 | AH11: =IF(AH$6=$N11,FV($V$3,$N11-1,,-$T11,0),0) -> 0 | AJ11: =IF(AJ$6=$N11,FV($V$3,$N11-1,,-$T11,0),0) -> 0 | AL11: =IF(AL$6=$N11,FV($V$3,$N11-1,,-$T11,0),0) -> 0 | AN11: =IF(AN$6=$N11,FV($V$3,$N11-1,,-$T11,0),0) -> 0 | AP11: =IF(AP$6=$N11,FV($V$3,$N11-1,,-$T11,0),0) -> 0 | AR11: =IF(AR$6=$N11,FV($V$3,$N11-1,,-$T11,0),0) -> 0 | AT11: =IF(AT$6=$N11,FV($V$3,$N11-1,,-$T11,0),0) -> 0 | AV11: =IF(AV$6=$N11,FV($V$3,$N11-1,,-$T11,0),0) -> 0 | AX11: =IF(AX$6=$N11,FV($V$3,$N11-1,,-$T11,0),0) -> 0 | AZ11: =IF(AZ$6=$N11,FV($V$3,$N11-1,,-$T11,0),0) -> 0
B12: =+B11+1 -> 2 | D12: 1 | F12: =F11 -> x | H12: x | J12: 1 | K12: 23 | L12: =L11 -> 1 | N12: =P12-O12 -> -1999 | O12: =O11 -> 2023 | P12: =J12+K12 -> 24 | R12: =R11 -> 1 | T12: =D12*R12 -> 1 | V12: =SUM(X12:AZ12)+SUM(J62:AL62) -> 0 | X12: =IF(X$6=$N12,FV($V$3,$N12-1,,-$T12,0),0) -> 0 | Z12: =IF(Z$6=$N12,FV($V$3,$N12-1,,-$T12,0),0) -> 0 | AB12: =IF(AB$6=$N12,FV($V$3,$N12-1,,-$T12,0),0) -> 0 | AD12: =IF(AD$6=$N12,FV($V$3,$N12-1,,-$T12,0),0) -> 0 | AF12: =IF(AF$6=$N12,FV($V$3,$N12-1,,-$T12,0),0) -> 0 | AH12: =IF(AH$6=$N12,FV($V$3,$N12-1,,-$T12,0),0) -> 0 | AJ12: =IF(AJ$6=$N12,FV($V$3,$N12-1,,-$T12,0),0) -> 0 | AL12: =IF(AL$6=$N12,FV($V$3,$N12-1,,-$T12,0),0) -> 0 | AN12: =IF(AN$6=$N12,FV($V$3,$N12-1,,-$T12,0),0) -> 0 | AP12: =IF(AP$6=$N12,FV($V$3,$N12-1,,-$T12,0),0) -> 0 | AR12: =IF(AR$6=$N12,FV($V$3,$N12-1,,-$T12,0),0) -> 0 | AT12: =IF(AT$6=$N12,FV($V$3,$N12-1,,-$T12,0),0) -> 0 | AV12: =IF(AV$6=$N12,FV($V$3,$N12-1,,-$T12,0),0) -> 0 | AX12: =IF(AX$6=$N12,FV($V$3,$N12-1,,-$T12,0),0) -> 0 | AZ12: =IF(AZ$6=$N12,FV($V$3,$N12-1,,-$T12,0),0) -> 0
B13: =+B12+1 -> 3 | D13: 1 | F13: =F12 -> x | H13: x | J13: 1 | K13: 23 | L13: =L12 -> 1 | N13: =P13-O13 -> -1999 | O13: =O12 -> 2023 | P13: =J13+K13 -> 24 | R13: =R12 -> 1 | T13: =D13*R13 -> 1 | V13: =SUM(X13:AZ13)+SUM(J63:AL63) -> 0 | X13: =IF(X$6=$N13,FV($V$3,$N13-1,,-$T13,0),0) -> 0 | Z13: =IF(Z$6=$N13,FV($V$3,$N13-1,,-$T13,0),0) -> 0 | AB13: =IF(AB$6=$N13,FV($V$3,$N13-1,,-$T13,0),0) -> 0 | AD13: =IF(AD$6=$N13,FV($V$3,$N13-1,,-$T13,0),0) -> 0 | AF13: =IF(AF$6=$N13,FV($V$3,$N13-1,,-$T13,0),0) -> 0 | AH13: =IF(AH$6=$N13,FV($V$3,$N13-1,,-$T13,0),0) -> 0 | AJ13: =IF(AJ$6=$N13,FV($V$3,$N13-1,,-$T13,0),0) -> 0 | AL13: =IF(AL$6=$N13,FV($V$3,$N13-1,,-$T13,0),0) -> 0 | AN13: =IF(AN$6=$N13,FV($V$3,$N13-1,,-$T13,0),0) -> 0 | AP13: =IF(AP$6=$N13,FV($V$3,$N13-1,,-$T13,0),0) -> 0 | AR13: =IF(AR$6=$N13,FV($V$3,$N13-1,,-$T13,0),0) -> 0 | AT13: =IF(AT$6=$N13,FV($V$3,$N13-1,,-$T13,0),0) -> 0 | AV13: =IF(AV$6=$N13,FV($V$3,$N13-1,,-$T13,0),0) -> 0 | AX13: =IF(AX$6=$N13,FV($V$3,$N13-1,,-$T13,0),0) -> 0 | AZ13: =IF(AZ$6=$N13,FV($V$3,$N13-1,,-$T13,0),0) -> 0
B14: =+B13+1 -> 4 | D14: 1 | F14: =F13 -> x | H14: x | J14: 1 | K14: 23 | L14: =L13 -> 1 | N14: =P14-O14 -> -1999 | O14: =O13 -> 2023 | P14: =J14+K14 -> 24 | R14: =R13 -> 1 | T14: =D14*R14 -> 1 | V14: =SUM(X14:AZ14)+SUM(J64:AL64) -> 0 | X14: =IF(X$6=$N14,FV($V$3,$N14-1,,-$T14,0),0) -> 0 | Z14: =IF(Z$6=$N14,FV($V$3,$N14-1,,-$T14,0),0) -> 0 | AB14: =IF(AB$6=$N14,FV($V$3,$N14-1,,-$T14,0),0) -> 0 | AD14: =IF(AD$6=$N14,FV($V$3,$N14-1,,-$T14,0),0) -> 0 | AF14: =IF(AF$6=$N14,FV($V$3,$N14-1,,-$T14,0),0) -> 0 | AH14: =IF(AH$6=$N14,FV($V$3,$N14-1,,-$T14,0),0) -> 0 | AJ14: =IF(AJ$6=$N14,FV($V$3,$N14-1,,-$T14,0),0) -> 0 | AL14: =IF(AL$6=$N14,FV($V$3,$N14-1,,-$T14,0),0) -> 0 | AN14: =IF(AN$6=$N14,FV($V$3,$N14-1,,-$T14,0),0) -> 0 | AP14: =IF(AP$6=$N14,FV($V$3,$N14-1,,-$T14,0),0) -> 0 | AR14: =IF(AR$6=$N14,FV($V$3,$N14-1,,-$T14,0),0) -> 0 | AT14: =IF(AT$6=$N14,FV($V$3,$N14-1,,-$T14,0),0) -> 0 | AV14: =IF(AV$6=$N14,FV($V$3,$N14-1,,-$T14,0),0) -> 0 | AX14: =IF(AX$6=$N14,FV($V$3,$N14-1,,-$T14,0),0) -> 0 | AZ14: =IF(AZ$6=$N14,FV($V$3,$N14-1,,-$T14,0),0) -> 0
B15: =+B14+1 -> 5 | D15: 1 | F15: =F14 -> x | H15: x | J15: 1 | K15: 23 | L15: =L14 -> 1 | N15: =P15-O15 -> -1999 | O15: =O14 -> 2023 | P15: =J15+K15 -> 24 | R15: =R14 -> 1 | T15: =D15*R15 -> 1 | V15: =SUM(X15:AZ15)+SUM(J65:AL65) -> 0 | X15: =IF(X$6=$N15,FV($V$3,$N15-1,,-$T15,0),0) -> 0 | Z15: =IF(Z$6=$N15,FV($V$3,$N15-1,,-$T15,0),0) -> 0 | AB15: =IF(AB$6=$N15,FV($V$3,$N15-1,,-$T15,0),0) -> 0 | AD15: =IF(AD$6=$N15,FV($V$3,$N15-1,,-$T15,0),0) -> 0 | AF15: =IF(AF$6=$N15,FV($V$3,$N15-1,,-$T15,0),0) -> 0 | AH15: =IF(AH$6=$N15,FV($V$3,$N15-1,,-$T15,0),0) -> 0 | AJ15: =IF(AJ$6=$N15,FV($V$3,$N15-1,,-$T15,0),0) -> 0 | AL15: =IF(AL$6=$N15,FV($V$3,$N15-1,,-$T15,0),0) -> 0 | AN15: =IF(AN$6=$N15,FV($V$3,$N15-1,,-$T15,0),0) -> 0 | AP15: =IF(AP$6=$N15,FV($V$3,$N15-1,,-$T15,0),0) -> 0 | AR15: =IF(AR$6=$N15,FV($V$3,$N15-1,,-$T15,0),0) -> 0 | AT15: =IF(AT$6=$N15,FV($V$3,$N15-1,,-$T15,0),0) -> 0 | AV15: =IF(AV$6=$N15,FV($V$3,$N15-1,,-$T15,0),0) -> 0 | AX15: =IF(AX$6=$N15,FV($V$3,$N15-1,,-$T15,0),0) -> 0 | AZ15: =IF(AZ$6=$N15,FV($V$3,$N15-1,,-$T15,0),0) -> 0
B16: =+B15+1 -> 6 | D16: 1 | F16: =F15 -> x | H16: x | J16: 1 | K16: 23 | L16: =L15 -> 1 | N16: =P16-O16 -> -1999 | O16: =O15 -> 2023 | P16: =J16+K16 -> 24 | R16: =R15 -> 1 | T16: =D16*R16 -> 1 | V16: =SUM(X16:AZ16)+SUM(J66:AL66) -> 0 | X16: =IF(X$6=$N16,FV($V$3,$N16-1,,-$T16,0),0) -> 0 | Z16: =IF(Z$6=$N16,FV($V$3,$N16-1,,-$T16,0),0) -> 0 | AB16: =IF(AB$6=$N16,FV($V$3,$N16-1,,-$T16,0),0) -> 0 | AD16: =IF(AD$6=$N16,FV($V$3,$N16-1,,-$T16,0),0) -> 0 | AF16: =IF(AF$6=$N16,FV($V$3,$N16-1,,-$T16,0),0) -> 0 | AH16: =IF(AH$6=$N16,FV($V$3,$N16-1,,-$T16,0),0) -> 0 | AJ16: =IF(AJ$6=$N16,FV($V$3,$N16-1,,-$T16,0),0) -> 0 | AL16: =IF(AL$6=$N16,FV($V$3,$N16-1,,-$T16,0),0) -> 0 | AN16: =IF(AN$6=$N16,FV($V$3,$N16-1,,-$T16,0),0) -> 0 | AP16: =IF(AP$6=$N16,FV($V$3,$N16-1,,-$T16,0),0) -> 0 | AR16: =IF(AR$6=$N16,FV($V$3,$N16-1,,-$T16,0),0) -> 0 | AT16: =IF(AT$6=$N16,FV($V$3,$N16-1,,-$T16,0),0) -> 0 | AV16: =IF(AV$6=$N16,FV($V$3,$N16-1,,-$T16,0),0) -> 0 | AX16: =IF(AX$6=$N16,FV($V$3,$N16-1,,-$T16,0),0) -> 0 | AZ16: =IF(AZ$6=$N16,FV($V$3,$N16-1,,-$T16,0),0) -> 0
B17: =+B16+1 -> 7 | D17: 1 | F17: =F16 -> x | H17: x | J17: 1 | K17: 23 | L17: =L16 -> 1 | N17: =P17-O17 -> -1999 | O17: =O16 -> 2023 | P17: =J17+K17 -> 24 | R17: =R16 -> 1 | T17: =D17*R17 -> 1 | V17: =SUM(X17:AZ17)+SUM(J67:AL67) -> 0 | X17: =IF(X$6=$N17,FV($V$3,$N17-1,,-$T17,0),0) -> 0 | Z17: =IF(Z$6=$N17,FV($V$3,$N17-1,,-$T17,0),0) -> 0 | AB17: =IF(AB$6=$N17,FV($V$3,$N17-1,,-$T17,0),0) -> 0 | AD17: =IF(AD$6=$N17,FV($V$3,$N17-1,,-$T17,0),0) -> 0 | AF17: =IF(AF$6=$N17,FV($V$3,$N17-1,,-$T17,0),0) -> 0 | AH17: =IF(AH$6=$N17,FV($V$3,$N17-1,,-$T17,0),0) -> 0 | AJ17: =IF(AJ$6=$N17,FV($V$3,$N17-1,,-$T17,0),0) -> 0 | AL17: =IF(AL$6=$N17,FV($V$3,$N17-1,,-$T17,0),0) -> 0 | AN17: =IF(AN$6=$N17,FV($V$3,$N17-1,,-$T17,0),0) -> 0 | AP17: =IF(AP$6=$N17,FV($V$3,$N17-1,,-$T17,0),0) -> 0 | AR17: =IF(AR$6=$N17,FV($V$3,$N17-1,,-$T17,0),0) -> 0 | AT17: =IF(AT$6=$N17,FV($V$3,$N17-1,,-$T17,0),0) -> 0 | AV17: =IF(AV$6=$N17,FV($V$3,$N17-1,,-$T17,0),0) -> 0 | AX17: =IF(AX$6=$N17,FV($V$3,$N17-1,,-$T17,0),0) -> 0 | AZ17: =IF(AZ$6=$N17,FV($V$3,$N17-1,,-$T17,0),0) -> 0
B18: =+B17+1 -> 8 | D18: 1 | F18: =F17 -> x | H18: x | J18: 1 | K18: 23 | L18: =L17 -> 1 | N18: =P18-O18 -> -1999 | O18: =O17 -> 2023 | P18: =J18+K18 -> 24 | R18: =R17 -> 1 | T18: =D18*R18 -> 1 | V18: =SUM(X18:AZ18)+SUM(J68:AL68) -> 0 | X18: =IF(X$6=$N18,FV($V$3,$N18-1,,-$T18,0),0) -> 0 | Z18: =IF(Z$6=$N18,FV($V$3,$N18-1,,-$T18,0),0) -> 0 | AB18: =IF(AB$6=$N18,FV($V$3,$N18-1,,-$T18,0),0) -> 0 | AD18: =IF(AD$6=$N18,FV($V$3,$N18-1,,-$T18,0),0) -> 0 | AF18: =IF(AF$6=$N18,FV($V$3,$N18-1,,-$T18,0),0) -> 0 | AH18: =IF(AH$6=$N18,FV($V$3,$N18-1,,-$T18,0),0) -> 0 | AJ18: =IF(AJ$6=$N18,FV($V$3,$N18-1,,-$T18,0),0) -> 0 | AL18: =IF(AL$6=$N18,FV($V$3,$N18-1,,-$T18,0),0) -> 0 | AN18: =IF(AN$6=$N18,FV($V$3,$N18-1,,-$T18,0),0) -> 0 | AP18: =IF(AP$6=$N18,FV($V$3,$N18-1,,-$T18,0),0) -> 0 | AR18: =IF(AR$6=$N18,FV($V$3,$N18-1,,-$T18,0),0) -> 0 | AT18: =IF(AT$6=$N18,FV($V$3,$N18-1,,-$T18,0),0) -> 0 | AV18: =IF(AV$6=$N18,FV($V$3,$N18-1,,-$T18,0),0) -> 0 | AX18: =IF(AX$6=$N18,FV($V$3,$N18-1,,-$T18,0),0) -> 0 | AZ18: =IF(AZ$6=$N18,FV($V$3,$N18-1,,-$T18,0),0) -> 0
B19: =+B18+1 -> 9 | D19: 1 | F19: =F18 -> x | H19: x | J19: 1 | K19: 23 | L19: =L18 -> 1 | N19: =P19-O19 -> -1999 | O19: =O18 -> 2023 | P19: =J19+K19 -> 24 | R19: =R18 -> 1 | T19: =D19*R19 -> 1 | V19: =SUM(X19:AZ19)+SUM(J69:AL69) -> 0 | X19: =IF(X$6=$N19,FV($V$3,$N19-1,,-$T19,0),0) -> 0 | Z19: =IF(Z$6=$N19,FV($V$3,$N19-1,,-$T19,0),0) -> 0 | AB19: =IF(AB$6=$N19,FV($V$3,$N19-1,,-$T19,0),0) -> 0 | AD19: =IF(AD$6=$N19,FV($V$3,$N19-1,,-$T19,0),0) -> 0 | AF19: =IF(AF$6=$N19,FV($V$3,$N19-1,,-$T19,0),0) -> 0 | AH19: =IF(AH$6=$N19,FV($V$3,$N19-1,,-$T19,0),0) -> 0 | AJ19: =IF(AJ$6=$N19,FV($V$3,$N19-1,,-$T19,0),0) -> 0 | AL19: =IF(AL$6=$N19,FV($V$3,$N19-1,,-$T19,0),0) -> 0 | AN19: =IF(AN$6=$N19,FV($V$3,$N19-1,,-$T19,0),0) -> 0 | AP19: =IF(AP$6=$N19,FV($V$3,$N19-1,,-$T19,0),0) -> 0 | AR19: =IF(AR$6=$N19,FV($V$3,$N19-1,,-$T19,0),0) -> 0 | AT19: =IF(AT$6=$N19,FV($V$3,$N19-1,,-$T19,0),0) -> 0 | AV19: =IF(AV$6=$N19,FV($V$3,$N19-1,,-$T19,0),0) -> 0 | AX19: =IF(AX$6=$N19,FV($V$3,$N19-1,,-$T19,0),0) -> 0 | AZ19: =IF(AZ$6=$N19,FV($V$3,$N19-1,,-$T19,0),0) -> 0
B20: =+B19+1 -> 10 | D20: 1 | F20: =F19 -> x | H20: x | J20: 1 | K20: 23 | L20: =L19 -> 1 | N20: =P20-O20 -> -1999 | O20: =O19 -> 2023 | P20: =J20+K20 -> 24 | R20: =R19 -> 1 | T20: =D20*R20 -> 1 | V20: =SUM(X20:AZ20)+SUM(J70:AL70) -> 0 | X20: =IF(X$6=$N20,FV($V$3,$N20-1,,-$T20,0),0) -> 0 | Z20: =IF(Z$6=$N20,FV($V$3,$N20-1,,-$T20,0),0) -> 0 | AB20: =IF(AB$6=$N20,FV($V$3,$N20-1,,-$T20,0),0) -> 0 | AD20: =IF(AD$6=$N20,FV($V$3,$N20-1,,-$T20,0),0) -> 0 | AF20: =IF(AF$6=$N20,FV($V$3,$N20-1,,-$T20,0),0) -> 0 | AH20: =IF(AH$6=$N20,FV($V$3,$N20-1,,-$T20,0),0) -> 0 | AJ20: =IF(AJ$6=$N20,FV($V$3,$N20-1,,-$T20,0),0) -> 0 | AL20: =IF(AL$6=$N20,FV($V$3,$N20-1,,-$T20,0),0) -> 0 | AN20: =IF(AN$6=$N20,FV($V$3,$N20-1,,-$T20,0),0) -> 0 | AP20: =IF(AP$6=$N20,FV($V$3,$N20-1,,-$T20,0),0) -> 0 | AR20: =IF(AR$6=$N20,FV($V$3,$N20-1,,-$T20,0),0) -> 0 | AT20: =IF(AT$6=$N20,FV($V$3,$N20-1,,-$T20,0),0) -> 0 | AV20: =IF(AV$6=$N20,FV($V$3,$N20-1,,-$T20,0),0) -> 0 | AX20: =IF(AX$6=$N20,FV($V$3,$N20-1,,-$T20,0),0) -> 0 | AZ20: =IF(AZ$6=$N20,FV($V$3,$N20-1,,-$T20,0),0) -> 0
B21: =+B20+1 -> 11 | D21: 1 | F21: =F20 -> x | H21: x | J21: 1 | K21: 23 | L21: =L20 -> 1 | N21: =P21-O21 -> -1999 | O21: =O20 -> 2023 | P21: =J21+K21 -> 24 | R21: =R20 -> 1 | T21: =D21*R21 -> 1 | V21: =SUM(X21:AZ21)+SUM(J71:AL71) -> 0 | X21: =IF(X$6=$N21,FV($V$3,$N21-1,,-$T21,0),0) -> 0 | Z21: =IF(Z$6=$N21,FV($V$3,$N21-1,,-$T21,0),0) -> 0 | AB21: =IF(AB$6=$N21,FV($V$3,$N21-1,,-$T21,0),0) -> 0 | AD21: =IF(AD$6=$N21,FV($V$3,$N21-1,,-$T21,0),0) -> 0 | AF21: =IF(AF$6=$N21,FV($V$3,$N21-1,,-$T21,0),0) -> 0 | AH21: =IF(AH$6=$N21,FV($V$3,$N21-1,,-$T21,0),0) -> 0 | AJ21: =IF(AJ$6=$N21,FV($V$3,$N21-1,,-$T21,0),0) -> 0 | AL21: =IF(AL$6=$N21,FV($V$3,$N21-1,,-$T21,0),0) -> 0 | AN21: =IF(AN$6=$N21,FV($V$3,$N21-1,,-$T21,0),0) -> 0 | AP21: =IF(AP$6=$N21,FV($V$3,$N21-1,,-$T21,0),0) -> 0 | AR21: =IF(AR$6=$N21,FV($V$3,$N21-1,,-$T21,0),0) -> 0 | AT21: =IF(AT$6=$N21,FV($V$3,$N21-1,,-$T21,0),0) -> 0 | AV21: =IF(AV$6=$N21,FV($V$3,$N21-1,,-$T21,0),0) -> 0 | AX21: =IF(AX$6=$N21,FV($V$3,$N21-1,,-$T21,0),0) -> 0 | AZ21: =IF(AZ$6=$N21,FV($V$3,$N21-1,,-$T21,0),0) -> 0
B22: =+B21+1 -> 12 | D22: 1 | F22: =F21 -> x | H22: x | J22: 1 | K22: 23 | L22: =L21 -> 1 | N22: =P22-O22 -> -1999 | O22: =O21 -> 2023 | P22: =J22+K22 -> 24 | R22: =R21 -> 1 | T22: =D22*R22 -> 1 | V22: =SUM(X22:AZ22)+SUM(J72:AL72) -> 0 | X22: =IF(X$6=$N22,FV($V$3,$N22-1,,-$T22,0),0) -> 0 | Z22: =IF(Z$6=$N22,FV($V$3,$N22-1,,-$T22,0),0) -> 0 | AB22: =IF(AB$6=$N22,FV($V$3,$N22-1,,-$T22,0),0) -> 0 | AD22: =IF(AD$6=$N22,FV($V$3,$N22-1,,-$T22,0),0) -> 0 | AF22: =IF(AF$6=$N22,FV($V$3,$N22-1,,-$T22,0),0) -> 0 | AH22: =IF(AH$6=$N22,FV($V$3,$N22-1,,-$T22,0),0) -> 0 | AJ22: =IF(AJ$6=$N22,FV($V$3,$N22-1,,-$T22,0),0) -> 0 | AL22: =IF(AL$6=$N22,FV($V$3,$N22-1,,-$T22,0),0) -> 0 | AN22: =IF(AN$6=$N22,FV($V$3,$N22-1,,-$T22,0),0) -> 0 | AP22: =IF(AP$6=$N22,FV($V$3,$N22-1,,-$T22,0),0) -> 0 | AR22: =IF(AR$6=$N22,FV($V$3,$N22-1,,-$T22,0),0) -> 0 | AT22: =IF(AT$6=$N22,FV($V$3,$N22-1,,-$T22,0),0) -> 0 | AV22: =IF(AV$6=$N22,FV($V$3,$N22-1,,-$T22,0),0) -> 0 | AX22: =IF(AX$6=$N22,FV($V$3,$N22-1,,-$T22,0),0) -> 0 | AZ22: =IF(AZ$6=$N22,FV($V$3,$N22-1,,-$T22,0),0) -> 0
B23: =+B22+1 -> 13 | D23: 1 | F23: =F22 -> x | H23: x | J23: 1 | K23: 23 | L23: =L22 -> 1 | N23: =P23-O23 -> -1999 | O23: =O22 -> 2023 | P23: =J23+K23 -> 24 | R23: =R22 -> 1 | T23: =D23*R23 -> 1 | V23: =SUM(X23:AZ23)+SUM(J73:AL73) -> 0 | X23: =IF(X$6=$N23,FV($V$3,$N23-1,,-$T23,0),0) -> 0 | Z23: =IF(Z$6=$N23,FV($V$3,$N23-1,,-$T23,0),0) -> 0 | AB23: =IF(AB$6=$N23,FV($V$3,$N23-1,,-$T23,0),0) -> 0 | AD23: =IF(AD$6=$N23,FV($V$3,$N23-1,,-$T23,0),0) -> 0 | AF23: =IF(AF$6=$N23,FV($V$3,$N23-1,,-$T23,0),0) -> 0 | AH23: =IF(AH$6=$N23,FV($V$3,$N23-1,,-$T23,0),0) -> 0 | AJ23: =IF(AJ$6=$N23,FV($V$3,$N23-1,,-$T23,0),0) -> 0 | AL23: =IF(AL$6=$N23,FV($V$3,$N23-1,,-$T23,0),0) -> 0 | AN23: =IF(AN$6=$N23,FV($V$3,$N23-1,,-$T23,0),0) -> 0 | AP23: =IF(AP$6=$N23,FV($V$3,$N23-1,,-$T23,0),0) -> 0 | AR23: =IF(AR$6=$N23,FV($V$3,$N23-1,,-$T23,0),0) -> 0 | AT23: =IF(AT$6=$N23,FV($V$3,$N23-1,,-$T23,0),0) -> 0 | AV23: =IF(AV$6=$N23,FV($V$3,$N23-1,,-$T23,0),0) -> 0 | AX23: =IF(AX$6=$N23,FV($V$3,$N23-1,,-$T23,0),0) -> 0 | AZ23: =IF(AZ$6=$N23,FV($V$3,$N23-1,,-$T23,0),0) -> 0
... B50: =+B49+1 -> 40 | D50: 1 | F50: =F49 -> x | H50: x | J50: 1 | K50: 23 | L50: =L49 -> 1 | N50: =P50-O50 -> -1999 | O50: =O49 -> 2023 | P50: =J50+K50 -> 24 | R50: =R49 -> 1 | T50: =D50*R50 -> 1 | V50: =SUM(X50:AZ50)+SUM(J100:AL100) -> 0 | X50: =IF(X$6=$N50,FV($V$3,$N50-1,,-$T50,0),0) -> 0 | Z50: =IF(Z$6=$N50,FV($V$3,$N50-1,,-$T50,0),0) -> 0 | AB50: =IF(AB$6=$N50,FV($V$3,$N50-1,,-$T50,0),0) -> 0 | AD50: =IF(AD$6=$N50,FV($V$3,$N50-1,,-$T50,0),0) -> 0 | AF50: =IF(AF$6=$N50,FV($V$3,$N50-1,,-$T50,0),0) -> 0 | AH50: =IF(AH$6=$N50,FV($V$3,$N50-1,,-$T50,0),0) -> 0 | AJ50: =IF(AJ$6=$N50,FV($V$3,$N50-1,,-$T50,0),0) -> 0 | AL50: =IF(AL$6=$N50,FV($V$3,$N50-1,,-$T50,0),0) -> 0 | AN50: =IF(AN$6=$N50,FV($V$3,$N50-1,,-$T50,0),0) -> 0 | AP50: =IF(AP$6=$N50,FV($V$3,$N50-1,,-$T50,0),0) -> 0 | AR50: =IF(AR$6=$N50,FV($V$3,$N50-1,,-$T50,0),0) -> 0 | AT50: =IF(AT$6=$N50,FV($V$3,$N50-1,,-$T50,0),0) -> 0 | AV50: =IF(AV$6=$N50,FV($V$3,$N50-1,,-$T50,0),0) -> 0 | AX50: =IF(AX$6=$N50,FV($V$3,$N50-1,,-$T50,0),0) -> 0 | AZ50: =IF(AZ$6=$N50,FV($V$3,$N50-1,,-$T50,0),0) -> 0
H52: Anticipated Expenditures, By Year | T52: =SUM(T11:T50) -> 40 | V52: =SUM(V11:V50) -> 0 | X52: =SUM(X11:X50) -> 0 | Z52: =SUM(Z11:Z50) -> 0 | AB52: =SUM(AB11:AB50) -> 0 | AD52: =SUM(AD11:AD50) -> 0 | AF52: =SUM(AF11:AF50) -> 0 | AH52: =SUM(AH11:AH50) -> 0 | AJ52: =SUM(AJ11:AJ50) -> 0 | AL52: =SUM(AL11:AL50) -> 0 | AN52: =SUM(AN11:AN50) -> 0 | AP52: =SUM(AP11:AP50) -> 0 | AR52: =SUM(AR11:AR50) -> 0 | AT52: =SUM(AT11:AT50) -> 0 | AV52: =SUM(AV11:AV50) -> 0 | AX52: =SUM(AX11:AX50) -> 0 | AZ52: =SUM(AZ11:AZ50) -> 0
B56: Line Item | J56: 16 | L56: 17 | N56: 18 | P56: 19 | R56: 20 | T56: =+R56+1 -> 21 | V56: =+T56+1 -> 22 | X56: =+V56+1 -> 23 | Z56: =+X56+1 -> 24 | AB56: =+Z56+1 -> 25 | AD56: =+AB56+1 -> 26 | AF56: =+AD56+1 -> 27 | AH56: =+AF56+1 -> 28 | AJ56: =+AH56+1 -> 29 | AL56: =+AJ56+1 -> 30
D57: Quantity | F57: Units | H57: Reserve Component Inventory | J57: =AZ7+1 -> 2039 | K57: =BA7+1 -> 1 | L57: =J57+1 -> 2040 | M57: =K57+1 -> 2 | N57: =L57+1 -> 2041 | O57: =M57+1 -> 3 | P57: =N57+1 -> 2042 | Q57: =O57+1 -> 4 | R57: =P57+1 -> 2043 | T57: =+R57+1 -> 2044 | U57: =S57+1 -> 1 | V57: =T57+1 -> 2045 | W57: =U57+1 -> 2 | X57: =V57+1 -> 2046 | Y57: =W57+1 -> 3 | Z57: =X57+1 -> 2047 | AA57: =Y57+1 -> 4 | AB57: =Z57+1 -> 2048 | AD57: =AB57+1 -> 2049 | AF57: =AD57+1 -> 2050 | AH57: =AF57+1 -> 2051 | AJ57: =AH57+1 -> 2052 | AL57: =AJ57+1 -> 2053
H59: =+H9 -> Roofs
B61: =+B11 -> 1 | D61: =+D11 -> 1 | F61: =+F11 -> x | H61: =+H11 -> x | J61: =IF(J$56=$N11,FV($V$3,$N11-1,,-$T11,0),0) -> 0 | L61: =IF(L$56=$N11,FV($V$3,$N11-1,,-$T11,0),0) -> 0 | N61: =IF(N$56=$N11,FV($V$3,$N11-1,,-$T11,0),0) -> 0 | P61: =IF(P$56=$N11,FV($V$3,$N11-1,,-$T11,0),0) -> 0 | R61: =IF(R$56=$N11,FV($V$3,$N11-1,,-$T11,0),0) -> 0 | T61: =IF(T$56=$N11,FV($V$3,$N11-1,,-$T11,0),0) -> 0 | V61: =IF(V$56=$N11,FV($V$3,$N11-1,,-$T11,0),0) -> 0 | X61: =IF(X$56=$N11,FV($V$3,$N11-1,,-$T11,0),0) -> 0 | Z61: =IF(Z$56=$N11,FV($V$3,$N11-1,,-$T11,0),0) -> 0 | AB61: =IF(AB$56=$N11,FV($V$3,$N11-1,,-$T11,0),0) -> 0 | AD61: =IF(AD$56=$N11,FV($V$3,$N11-1,,-$T11,0),0) -> 0 | AF61: =IF(AF$56=$N11,FV($V$3,$N11-1,,-$T11,0),0) -> 0 | AH61: =IF(AH$56=$N11,FV($V$3,$N11-1,,-$T11,0),0) -> 0 | AJ61: =IF(AJ$56=$N11,FV($V$3,$N11-1,,-$T11,0),0) -> 0 | AL61: =IF(AL$56=$N11,FV($V$3,$N11-1,,-$T11,0),0) -> 0
B62: =+B12 -> 2 | D62: =+D12 -> 1 | F62: =+F12 -> x | H62: =+H12 -> x | J62: =IF(J$56=$N12,FV($V$3,$N12-1,,-$T12,0),0) -> 0 | L62: =IF(L$56=$N12,FV($V$3,$N12-1,,-$T12,0),0) -> 0 | N62: =IF(N$56=$N12,FV($V$3,$N12-1,,-$T12,0),0) -> 0 | P62: =IF(P$56=$N12,FV($V$3,$N12-1,,-$T12,0),0) -> 0 | R62: =IF(R$56=$N12,FV($V$3,$N12-1,,-$T12,0),0) -> 0 | T62: =IF(T$56=$N12,FV($V$3,$N12-1,,-$T12,0),0) -> 0 | V62: =IF(V$56=$N12,FV($V$3,$N12-1,,-$T12,0),0) -> 0 | X62: =IF(X$56=$N12,FV($V$3,$N12-1,,-$T12,0),0) -> 0 | Z62: =IF(Z$56=$N12,FV($V$3,$N12-1,,-$T12,0),0) -> 0 | AB62: =IF(AB$56=$N12,FV($V$3,$N12-1,,-$T12,0),0) -> 0 | AD62: =IF(AD$56=$N12,FV($V$3,$N12-1,,-$T12,0),0) -> 0 | AF62: =IF(AF$56=$N12,FV($V$3,$N12-1,,-$T12,0),0) -> 0 | AH62: =IF(AH$56=$N12,FV($V$3,$N12-1,,-$T12,0),0) -> 0 | AJ62: =IF(AJ$56=$N12,FV($V$3,$N12-1,,-$T12,0),0) -> 0 | AL62: =IF(AL$56=$N12,FV($V$3,$N12-1,,-$T12,0),0) -> 0
B63: =+B13 -> 3 | D63: =+D13 -> 1 | F63: =+F13 -> x | H63: =+H13 -> x | J63: =IF(J$56=$N13,FV($V$3,$N13-1,,-$T13,0),0) -> 0 | L63: =IF(L$56=$N13,FV($V$3,$N13-1,,-$T13,0),0) -> 0 | N63: =IF(N$56=$N13,FV($V$3,$N13-1,,-$T13,0),0) -> 0 | P63: =IF(P$56=$N13,FV($V$3,$N13-1,,-$T13,0),0) -> 0 | R63: =IF(R$56=$N13,FV($V$3,$N13-1,,-$T13,0),0) -> 0 | T63: =IF(T$56=$N13,FV($V$3,$N13-1,,-$T13,0),0) -> 0 | V63: =IF(V$56=$N13,FV($V$3,$N13-1,,-$T13,0),0) -> 0 | X63: =IF(X$56=$N13,FV($V$3,$N13-1,,-$T13,0),0) -> 0 | Z63: =IF(Z$56=$N13,FV($V$3,$N13-1,,-$T13,0),0) -> 0 | AB63: =IF(AB$56=$N13,FV($V$3,$N13-1,,-$T13,0),0) -> 0 | AD63: =IF(AD$56=$N13,FV($V$3,$N13-1,,-$T13,0),0) -> 0 | AF63: =IF(AF$56=$N13,FV($V$3,$N13-1,,-$T13,0),0) -> 0 | AH63: =IF(AH$56=$N13,FV($V$3,$N13-1,,-$T13,0),0) -> 0 | AJ63: =IF(AJ$56=$N13,FV($V$3,$N13-1,,-$T13,0),0) -> 0 | AL63: =IF(AL$56=$N13,FV($V$3,$N13-1,,-$T13,0),0) -> 0
B64: =+B14 -> 4 | D64: =+D14 -> 1 | F64: =+F14 -> x | H64: =+H14 -> x | J64: =IF(J$56=$N14,FV($V$3,$N14-1,,-$T14,0),0) -> 0 | L64: =IF(L$56=$N14,FV($V$3,$N14-1,,-$T14,0),0) -> 0 | N64: =IF(N$56=$N14,FV($V$3,$N14-1,,-$T14,0),0) -> 0 | P64: =IF(P$56=$N14,FV($V$3,$N14-1,,-$T14,0),0) -> 0 | R64: =IF(R$56=$N14,FV($V$3,$N14-1,,-$T14,0),0) -> 0 | T64: =IF(T$56=$N14,FV($V$3,$N14-1,,-$T14,0),0) -> 0 | V64: =IF(V$56=$N14,FV($V$3,$N14-1,,-$T14,0),0) -> 0 | X64: =IF(X$56=$N14,FV($V$3,$N14-1,,-$T14,0),0) -> 0 | Z64: =IF(Z$56=$N14,FV($V$3,$N14-1,,-$T14,0),0) -> 0 | AB64: =IF(AB$56=$N14,FV($V$3,$N14-1,,-$T14,0),0) -> 0 | AD64: =IF(AD$56=$N14,FV($V$3,$N14-1,,-$T14,0),0) -> 0 | AF64: =IF(AF$56=$N14,FV($V$3,$N14-1,,-$T14,0),0) -> 0 | AH64: =IF(AH$56=$N14,FV($V$3,$N14-1,,-$T14,0),0) -> 0 | AJ64: =IF(AJ$56=$N14,FV($V$3,$N14-1,,-$T14,0),0) -> 0 | AL64: =IF(AL$56=$N14,FV($V$3,$N14-1,,-$T14,0),0) -> 0
B65: =+B15 -> 5 | D65: =+D15 -> 1 | F65: =+F15 -> x | H65: =+H15 -> x | J65: =IF(J$56=$N15,FV($V$3,$N15-1,,-$T15,0),0) -> 0 | L65: =IF(L$56=$N15,FV($V$3,$N15-1,,-$T15,0),0) -> 0 | N65: =IF(N$56=$N15,FV($V$3,$N15-1,,-$T15,0),0) -> 0 | P65: =IF(P$56=$N15,FV($V$3,$N15-1,,-$T15,0),0) -> 0 | R65: =IF(R$56=$N15,FV($V$3,$N15-1,,-$T15,0),0) -> 0 | T65: =IF(T$56=$N15,FV($V$3,$N15-1,,-$T15,0),0) -> 0 | V65: =IF(V$56=$N15,FV($V$3,$N15-1,,-$T15,0),0) -> 0 | X65: =IF(X$56=$N15,FV($V$3,$N15-1,,-$T15,0),0) -> 0 | Z65: =IF(Z$56=$N15,FV($V$3,$N15-1,,-$T15,0),0) -> 0 | AB65: =IF(AB$56=$N15,FV($V$3,$N15-1,,-$T15,0),0) -> 0 | AD65: =IF(AD$56=$N15,FV($V$3,$N15-1,,-$T15,0),0) -> 0 | AF65: =IF(AF$56=$N15,FV($V$3,$N15-1,,-$T15,0),0) -> 0 | AH65: =IF(AH$56=$N15,FV($V$3,$N15-1,,-$T15,0),0) -> 0 | AJ65: =IF(AJ$56=$N15,FV($V$3,$N15-1,,-$T15,0),0) -> 0 | AL65: =IF(AL$56=$N15,FV($V$3,$N15-1,,-$T15,0),0) -> 0
B66: =+B16 -> 6 | D66: =+D16 -> 1 | F66: =+F16 -> x | H66: =+H16 -> x | J66: =IF(J$56=$N16,FV($V$3,$N16-1,,-$T16,0),0) -> 0 | L66: =IF(L$56=$N16,FV($V$3,$N16-1,,-$T16,0),0) -> 0 | N66: =IF(N$56=$N16,FV($V$3,$N16-1,,-$T16,0),0) -> 0 | P66: =IF(P$56=$N16,FV($V$3,$N16-1,,-$T16,0),0) -> 0 | R66: =IF(R$56=$N16,FV($V$3,$N16-1,,-$T16,0),0) -> 0 | T66: =IF(T$56=$N16,FV($V$3,$N16-1,,-$T16,0),0) -> 0 | V66: =IF(V$56=$N16,FV($V$3,$N16-1,,-$T16,0),0) -> 0 | X66: =IF(X$56=$N16,FV($V$3,$N16-1,,-$T16,0),0) -> 0 | Z66: =IF(Z$56=$N16,FV($V$3,$N16-1,,-$T16,0),0) -> 0 | AB66: =IF(AB$56=$N16,FV($V$3,$N16-1,,-$T16,0),0) -> 0 | AD66: =IF(AD$56=$N16,FV($V$3,$N16-1,,-$T16,0),0) -> 0 | AF66: =IF(AF$56=$N16,FV($V$3,$N16-1,,-$T16,0),0) -> 0 | AH66: =IF(AH$56=$N16,FV($V$3,$N16-1,,-$T16,0),0) -> 0 | AJ66: =IF(AJ$56=$N16,FV($V$3,$N16-1,,-$T16,0),0) -> 0 | AL66: =IF(AL$56=$N16,FV($V$3,$N16-1,,-$T16,0),0) -> 0
B67: =+B17 -> 7 | D67: =+D17 -> 1 | F67: =+F17 -> x | H67: =+H17 -> x | J67: =IF(J$56=$N17,FV($V$3,$N17-1,,-$T17,0),0) -> 0 | L67: =IF(L$56=$N17,FV($V$3,$N17-1,,-$T17,0),0) -> 0 | N67: =IF(N$56=$N17,FV($V$3,$N17-1,,-$T17,0),0) -> 0 | P67: =IF(P$56=$N17,FV($V$3,$N17-1,,-$T17,0),0) -> 0 | R67: =IF(R$56=$N17,FV($V$3,$N17-1,,-$T17,0),0) -> 0 | T67: =IF(T$56=$N17,FV($V$3,$N17-1,,-$T17,0),0) -> 0 | V67: =IF(V$56=$N17,FV($V$3,$N17-1,,-$T17,0),0) -> 0 | X67: =IF(X$56=$N17,FV($V$3,$N17-1,,-$T17,0),0) -> 0 | Z67: =IF(Z$56=$N17,FV($V$3,$N17-1,,-$T17,0),0) -> 0 | AB67: =IF(AB$56=$N17,FV($V$3,$N17-1,,-$T17,0),0) -> 0 | AD67: =IF(AD$56=$N17,FV($V$3,$N17-1,,-$T17,0),0) -> 0 | AF67: =IF(AF$56=$N17,FV($V$3,$N17-1,,-$T17,0),0) -> 0 | AH67: =IF(AH$56=$N17,FV($V$3,$N17-1,,-$T17,0),0) -> 0 | AJ67: =IF(AJ$56=$N17,FV($V$3,$N17-1,,-$T17,0),0) -> 0 | AL67: =IF(AL$56=$N17,FV($V$3,$N17-1,,-$T17,0),0) -> 0
B68: =+B18 -> 8 | D68: =+D18 -> 1 | F68: =+F18 -> x | H68: =+H18 -> x | J68: =IF(J$56=$N18,FV($V$3,$N18-1,,-$T18,0),0) -> 0 | L68: =IF(L$56=$N18,FV($V$3,$N18-1,,-$T18,0),0) -> 0 | N68: =IF(N$56=$N18,FV($V$3,$N18-1,,-$T18,0),0) -> 0 | P68: =IF(P$56=$N18,FV($V$3,$N18-1,,-$T18,0),0) -> 0 | R68: =IF(R$56=$N18,FV($V$3,$N18-1,,-$T18,0),0) -> 0 | T68: =IF(T$56=$N18,FV($V$3,$N18-1,,-$T18,0),0) -> 0 | V68: =IF(V$56=$N18,FV($V$3,$N18-1,,-$T18,0),0) -> 0 | X68: =IF(X$56=$N18,FV($V$3,$N18-1,,-$T18,0),0) -> 0 | Z68: =IF(Z$56=$N18,FV($V$3,$N18-1,,-$T18,0),0) -> 0 | AB68: =IF(AB$56=$N18,FV($V$3,$N18-1,,-$T18,0),0) -> 0 | AD68: =IF(AD$56=$N18,FV($V$3,$N18-1,,-$T18,0),0) -> 0 | AF68: =IF(AF$56=$N18,FV($V$3,$N18-1,,-$T18,0),0) -> 0 | AH68: =IF(AH$56=$N18,FV($V$3,$N18-1,,-$T18,0),0) -> 0 | AJ68: =IF(AJ$56=$N18,FV($V$3,$N18-1,,-$T18,0),0) -> 0 | AL68: =IF(AL$56=$N18,FV($V$3,$N18-1,,-$T18,0),0) -> 0
B69: =+B19 -> 9 | D69: =+D19 -> 1 | F69: =+F19 -> x | H69: =+H19 -> x | J69: =IF(J$56=$N19,FV($V$3,$N19-1,,-$T19,0),0) -> 0 | L69: =IF(L$56=$N19,FV($V$3,$N19-1,,-$T19,0),0) -> 0 | N69: =IF(N$56=$N19,FV($V$3,$N19-1,,-$T19,0),0) -> 0 | P69: =IF(P$56=$N19,FV($V$3,$N19-1,,-$T19,0),0) -> 0 | R69: =IF(R$56=$N19,FV($V$3,$N19-1,,-$T19,0),0) -> 0 | T69: =IF(T$56=$N19,FV($V$3,$N19-1,,-$T19,0),0) -> 0 | V69: =IF(V$56=$N19,FV($V$3,$N19-1,,-$T19,0),0) -> 0 | X69: =IF(X$56=$N19,FV($V$3,$N19-1,,-$T19,0),0) -> 0 | Z69: =IF(Z$56=$N19,FV($V$3,$N19-1,,-$T19,0),0) -> 0 | AB69: =IF(AB$56=$N19,FV($V$3,$N19-1,,-$T19,0),0) -> 0 | AD69: =IF(AD$56=$N19,FV($V$3,$N19-1,,-$T19,0),0) -> 0 | AF69: =IF(AF$56=$N19,FV($V$3,$N19-1,,-$T19,0),0) -> 0 | AH69: =IF(AH$56=$N19,FV($V$3,$N19-1,,-$T19,0),0) -> 0 | AJ69: =IF(AJ$56=$N19,FV($V$3,$N19-1,,-$T19,0),0) -> 0 | AL69: =IF(AL$56=$N19,FV($V$3,$N19-1,,-$T19,0),0) -> 0
B70: =+B20 -> 10 | D70: =+D20 -> 1 | F70: =+F20 -> x | H70: =+H20 -> x | J70: =IF(J$56=$N20,FV($V$3,$N20-1,,-$T20,0),0) -> 0 | L70: =IF(L$56=$N20,FV($V$3,$N20-1,,-$T20,0),0) -> 0 | N70: =IF(N$56=$N20,FV($V$3,$N20-1,,-$T20,0),0) -> 0 | P70: =IF(P$56=$N20,FV($V$3,$N20-1,,-$T20,0),0) -> 0 | R70: =IF(R$56=$N20,FV($V$3,$N20-1,,-$T20,0),0) -> 0 | T70: =IF(T$56=$N20,FV($V$3,$N20-1,,-$T20,0),0) -> 0 | V70: =IF(V$56=$N20,FV($V$3,$N20-1,,-$T20,0),0) -> 0 | X70: =IF(X$56=$N20,FV($V$3,$N20-1,,-$T20,0),0) -> 0 | Z70: =IF(Z$56=$N20,FV($V$3,$N20-1,,-$T20,0),0) -> 0 | AB70: =IF(AB$56=$N20,FV($V$3,$N20-1,,-$T20,0),0) -> 0 | AD70: =IF(AD$56=$N20,FV($V$3,$N20-1,,-$T20,0),0) -> 0 | AF70: =IF(AF$56=$N20,FV($V$3,$N20-1,,-$T20,0),0) -> 0 | AH70: =IF(AH$56=$N20,FV($V$3,$N20-1,,-$T20,0),0) -> 0 | AJ70: =IF(AJ$56=$N20,FV($V$3,$N20-1,,-$T20,0),0) -> 0 | AL70: =IF(AL$56=$N20,FV($V$3,$N20-1,,-$T20,0),0) -> 0
B71: =+B21 -> 11 | D71: =+D21 -> 1 | F71: =+F21 -> x | H71: =+H21 -> x | J71: =IF(J$56=$N21,FV($V$3,$N21-1,,-$T21,0),0) -> 0 | L71: =IF(L$56=$N21,FV($V$3,$N21-1,,-$T21,0),0) -> 0 | N71: =IF(N$56=$N21,FV($V$3,$N21-1,,-$T21,0),0) -> 0 | P71: =IF(P$56=$N21,FV($V$3,$N21-1,,-$T21,0),0) -> 0 | R71: =IF(R$56=$N21,FV($V$3,$N21-1,,-$T21,0),0) -> 0 | T71: =IF(T$56=$N21,FV($V$3,$N21-1,,-$T21,0),0) -> 0 | V71: =IF(V$56=$N21,FV($V$3,$N21-1,,-$T21,0),0) -> 0 | X71: =IF(X$56=$N21,FV($V$3,$N21-1,,-$T21,0),0) -> 0 | Z71: =IF(Z$56=$N21,FV($V$3,$N21-1,,-$T21,0),0) -> 0 | AB71: =IF(AB$56=$N21,FV($V$3,$N21-1,,-$T21,0),0) -> 0 | AD71: =IF(AD$56=$N21,FV($V$3,$N21-1,,-$T21,0),0) -> 0 | AF71: =IF(AF$56=$N21,FV($V$3,$N21-1,,-$T21,0),0) -> 0 | AH71: =IF(AH$56=$N21,FV($V$3,$N21-1,,-$T21,0),0) -> 0 | AJ71: =IF(AJ$56=$N21,FV($V$3,$N21-1,,-$T21,0),0) -> 0 | AL71: =IF(AL$56=$N21,FV($V$3,$N21-1,,-$T21,0),0) -> 0
B72: =+B22 -> 12 | D72: =+D22 -> 1 | F72: =+F22 -> x | H72: =+H22 -> x | J72: =IF(J$56=$N22,FV($V$3,$N22-1,,-$T22,0),0) -> 0 | L72: =IF(L$56=$N22,FV($V$3,$N22-1,,-$T22,0),0) -> 0 | N72: =IF(N$56=$N22,FV($V$3,$N22-1,,-$T22,0),0) -> 0 | P72: =IF(P$56=$N22,FV($V$3,$N22-1,,-$T22,0),0) -> 0 | R72: =IF(R$56=$N22,FV($V$3,$N22-1,,-$T22,0),0) -> 0 | T72: =IF(T$56=$N22,FV($V$3,$N22-1,,-$T22,0),0) -> 0 | V72: =IF(V$56=$N22,FV($V$3,$N22-1,,-$T22,0),0) -> 0 | X72: =IF(X$56=$N22,FV($V$3,$N22-1,,-$T22,0),0) -> 0 | Z72: =IF(Z$56=$N22,FV($V$3,$N22-1,,-$T22,0),0) -> 0 | AB72: =IF(AB$56=$N22,FV($V$3,$N22-1,,-$T22,0),0) -> 0 | AD72: =IF(AD$56=$N22,FV($V$3,$N22-1,,-$T22,0),0) -> 0 | AF72: =IF(AF$56=$N22,FV($V$3,$N22-1,,-$T22,0),0) -> 0 | AH72: =IF(AH$56=$N22,FV($V$3,$N22-1,,-$T22,0),0) -> 0 | AJ72: =IF(AJ$56=$N22,FV($V$3,$N22-1,,-$T22,0),0) -> 0 | AL72: =IF(AL$56=$N22,FV($V$3,$N22-1,,-$T22,0),0) -> 0
... B100: =+B50 -> 40 | D100: =+D50 -> 1 | F100: =+F50 -> x | H100: =+H50 -> x | J100: =IF(J$56=$N50,FV($V$3,$N50-1,,-$T50,0),0) -> 0 | L100: =IF(L$56=$N50,FV($V$3,$N50-1,,-$T50,0),0) -> 0 | N100: =IF(N$56=$N50,FV($V$3,$N50-1,,-$T50,0),0) -> 0 | P100: =IF(P$56=$N50,FV($V$3,$N50-1,,-$T50,0),0) -> 0 | R100: =IF(R$56=$N50,FV($V$3,$N50-1,,-$T50,0),0) -> 0 | T100: =IF(T$56=$N50,FV($V$3,$N50-1,,-$T50,0),0) -> 0 | V100: =IF(V$56=$N50,FV($V$3,$N50-1,,-$T50,0),0) -> 0 | X100: =IF(X$56=$N50,FV($V$3,$N50-1,,-$T50,0),0) -> 0 | Z100: =IF(Z$56=$N50,FV($V$3,$N50-1,,-$T50,0),0) -> 0 | AB100: =IF(AB$56=$N50,FV($V$3,$N50-1,,-$T50,0),0) -> 0 | AD100: =IF(AD$56=$N50,FV($V$3,$N50-1,,-$T50,0),0) -> 0 | AF100: =IF(AF$56=$N50,FV($V$3,$N50-1,,-$T50,0),0) -> 0 | AH100: =IF(AH$56=$N50,FV($V$3,$N50-1,,-$T50,0),0) -> 0 | AJ100: =IF(AJ$56=$N50,FV($V$3,$N50-1,,-$T50,0),0) -> 0 | AL100: =IF(AL$56=$N50,FV($V$3,$N50-1,,-$T50,0),0) -> 0
H102: =+H52 -> Anticipated Expenditures, By Year | J102: =SUM(J61:J100) -> 0 | L102: =SUM(L61:L100) -> 0 | N102: =SUM(N61:N100) -> 0 | P102: =SUM(P61:P100) -> 0 | R102: =SUM(R61:R100) -> 0 | T102: =SUM(T61:T100) -> 0 | V102: =SUM(V61:V100) -> 0 | X102: =SUM(X61:X100) -> 0 | Z102: =SUM(Z61:Z100) -> 0 | AB102: =SUM(AB61:AB100) -> 0 | AD102: =SUM(AD61:AD100) -> 0 | AF102: =SUM(AF61:AF100) -> 0 | AH102: =SUM(AH61:AH100) -> 0 | AJ102: =SUM(AJ61:AJ100) -> 0 | AL102: =SUM(AL61:AL100) -> 0

Sheet Maintain (PRN) 1
G3: Exhibit B
G5: RESERVE EXPENDITURES | U5: Explanatory Notes:
G6: for | T6: 1) | U6: =+'Roofs 1'!V3 -> 0.03 | V6: is the estimated future Inflation Rate for estimating Future Replacement Costs.
G7: =+'Roofs 1'!H5 -> Association | T7: 2) | U7: Fiscal Year is beginning January 1 and ending December 31.
A9: Line Item | C9: Estimated | I9: Estimated Year Last Replaced | K9: Life Analysis, Years | O9: Estimated Year of 1st Replacement | Q9: =+'Roofs 1'!R6 -> 2024 Unit Cost | S9: =+'Roofs 1'!T6 -> 2024 Cost of Replacement | U9: Total Future Cost of Replacement | W9: 1 | Y9: 2 | AA9: 3 | AC9: 4 | AE9: 5 | AG9: 6 | AI9: 7 | AK9: 8 | AM9: 9 | AO9: 10 | AQ9: 11 | AS9: 12 | AU9: 13 | AW9: 14 | AY9: 15
C10: Quantity | E10: Units | G10: Reserve Component Inventory | K10: Useful | M10: Remaining | W10: =+'Roofs 1'!X7 -> 2024 | Y10: =W10+1 -> 2025 | Z10: =X10+1 -> 1 | AA10: =Y10+1 -> 2026 | AB10: =Z10+1 -> 2 | AC10: =AA10+1 -> 2027 | AD10: =AB10+1 -> 3 | AE10: =AC10+1 -> 2028 | AF10: =AD10+1 -> 4 | ... AY10: =AW10+1 -> 2038
G12: ELEMENTS
A14: ='Roofs 1'!B50+1 -> 41 | C14: 1 | E14: x | G14: x | I14: x | K14: x | M14: 1 | N14: ='Roofs 1'!P4 -> 2023 | O14: 1 | Q14: 1 | S14: =C14*Q14 -> 1 | U14: =SUM(W14:AY14)+SUM(I47:AK47) -> 47.575416 | W14: =S14 -> 1 | Y14: =FV($U$6,W$9,,-$S14,0) -> 1.03 | AA14: =FV($U$6,Y$9,,-$S14,0) -> 1.0609 | AC14: =FV($U$6,AA$9,,-$S14,0) -> 1.092727 | AE14: =FV($U$6,AC$9,,-$S14,0) -> 1.1255088 | AG14: =FV($U$6,AE$9,,-$S14,0) -> 1.1592741 | AI14: =FV($U$6,AG$9,,-$S14,0) -> 1.1940523 | AK14: =FV($U$6,AI$9,,-$S14,0) -> 1.2298739 | AM14: =FV($U$6,AK$9,,-$S14,0) -> 1.2667701 | AO14: =FV($U$6,AM$9,,-$S14,0) -> 1.3047732 | AQ14: =FV($U$6,AO$9,,-$S14,0) -> 1.3439164 | AS14: =FV($U$6,AQ$9,,-$S14,0) -> 1.3842339 | AU14: =FV($U$6,AS$9,,-$S14,0) -> 1.4257609 | AW14: =FV($U$6,AU$9,,-$S14,0) -> 1.4685337 | AY14: =FV($U$6,AW$9,,-$S14,0) -> 1.5125897
A15: =+A14+1 -> 42 | C15: 1 | E15: x | G15: x | I15: x | K15: x | M15: 1 | N15: =N14 -> 2023 | O15: 1 | Q15: 1 | S15: =C15*Q15 -> 1 | U15: =SUM(W15:AY15)+SUM(I48:AK48) -> 47.575416 | W15: =S15 -> 1 | Y15: =FV($U$6,W$9,,-$S15,0) -> 1.03 | AA15: =FV($U$6,Y$9,,-$S15,0) -> 1.0609 | AC15: =FV($U$6,AA$9,,-$S15,0) -> 1.092727 | AE15: =FV($U$6,AC$9,,-$S15,0) -> 1.1255088 | AG15: =FV($U$6,AE$9,,-$S15,0) -> 1.1592741 | AI15: =FV($U$6,AG$9,,-$S15,0) -> 1.1940523 | AK15: =FV($U$6,AI$9,,-$S15,0) -> 1.2298739 | AM15: =FV($U$6,AK$9,,-$S15,0) -> 1.2667701 | AO15: =FV($U$6,AM$9,,-$S15,0) -> 1.3047732 | AQ15: =FV($U$6,AO$9,,-$S15,0) -> 1.3439164 | AS15: =FV($U$6,AQ$9,,-$S15,0) -> 1.3842339 | AU15: =FV($U$6,AS$9,,-$S15,0) -> 1.4257609 | AW15: =FV($U$6,AU$9,,-$S15,0) -> 1.4685337 | AY15: =FV($U$6,AW$9,,-$S15,0) -> 1.5125897
A16: =+A15+1 -> 43 | C16: 1 | E16: x | G16: x | I16: x | K16: x | M16: 1 | N16: =N15 -> 2023 | O16: 1 | Q16: 1 | S16: =C16*Q16 -> 1 | U16: =SUM(W16:AY16)+SUM(I49:AK49) -> 47.575416 | W16: =S16 -> 1 | Y16: =FV($U$6,W$9,,-$S16,0) -> 1.03 | AA16: =FV($U$6,Y$9,,-$S16,0) -> 1.0609 | AC16: =FV($U$6,AA$9,,-$S16,0) -> 1.092727 | AE16: =FV($U$6,AC$9,,-$S16,0) -> 1.1255088 | AG16: =FV($U$6,AE$9,,-$S16,0) -> 1.1592741 | AI16: =FV($U$6,AG$9,,-$S16,0) -> 1.1940523 | AK16: =FV($U$6,AI$9,,-$S16,0) -> 1.2298739 | AM16: =FV($U$6,AK$9,,-$S16,0) -> 1.2667701 | AO16: =FV($U$6,AM$9,,-$S16,0) -> 1.3047732 | AQ16: =FV($U$6,AO$9,,-$S16,0) -> 1.3439164 | AS16: =FV($U$6,AQ$9,,-$S16,0) -> 1.3842339 | AU16: =FV($U$6,AS$9,,-$S16,0) -> 1.4257609 | AW16: =FV($U$6,AU$9,,-$S16,0) -> 1.4685337 | AY16: =FV($U$6,AW$9,,-$S16,0) -> 1.5125897
A17: =+A16+1 -> 44 | C17: 1 | E17: x | G17: x | I17: x | K17: x | M17: 1 | N17: =N16 -> 2023 | O17: 1 | Q17: 1 | S17: =C17*Q17 -> 1 | U17: =SUM(W17:AY17)+SUM(I50:AK50) -> 47.575416 | W17: =S17 -> 1 | Y17: =FV($U$6,W$9,,-$S17,0) -> 1.03 | AA17: =FV($U$6,Y$9,,-$S17,0) -> 1.0609 | AC17: =FV($U$6,AA$9,,-$S17,0) -> 1.092727 | AE17: =FV($U$6,AC$9,,-$S17,0) -> 1.1255088 | AG17: =FV($U$6,AE$9,,-$S17,0) -> 1.1592741 | AI17: =FV($U$6,AG$9,,-$S17,0) -> 1.1940523 | AK17: =FV($U$6,AI$9,,-$S17,0) -> 1.2298739 | AM17: =FV($U$6,AK$9,,-$S17,0) -> 1.2667701 | AO17: =FV($U$6,AM$9,,-$S17,0) -> 1.3047732 | AQ17: =FV($U$6,AO$9,,-$S17,0) -> 1.3439164 | AS17: =FV($U$6,AQ$9,,-$S17,0) -> 1.3842339 | AU17: =FV($U$6,AS$9,,-$S17,0) -> 1.4257609 | AW17: =FV($U$6,AU$9,,-$S17,0) -> 1.4685337 | AY17: =FV($U$6,AW$9,,-$S17,0) -> 1.5125897
A18: =+A17+1 -> 45 | C18: 1 | E18: x | G18: x | I18: x | K18: x | M18: 1 | N18: =N17 -> 2023 | O18: 1 | Q18: 1 | S18: =C18*Q18 -> 1 | U18: =SUM(W18:AY18)+SUM(I51:AK51) -> 47.575416 | W18: =S18 -> 1 | Y18: =FV($U$6,W$9,,-$S18,0) -> 1.03 | AA18: =FV($U$6,Y$9,,-$S18,0) -> 1.0609 | AC18: =FV($U$6,AA$9,,-$S18,0) -> 1.092727 | AE18: =FV($U$6,AC$9,,-$S18,0) -> 1.1255088 | AG18: =FV($U$6,AE$9,,-$S18,0) -> 1.1592741 | AI18: =FV($U$6,AG$9,,-$S18,0) -> 1.1940523 | AK18: =FV($U$6,AI$9,,-$S18,0) -> 1.2298739 | AM18: =FV($U$6,AK$9,,-$S18,0) -> 1.2667701 | AO18: =FV($U$6,AM$9,,-$S18,0) -> 1.3047732 | AQ18: =FV($U$6,AO$9,,-$S18,0) -> 1.3439164 | AS18: =FV($U$6,AQ$9,,-$S18,0) -> 1.3842339 | AU18: =FV($U$6,AS$9,,-$S18,0) -> 1.4257609 | AW18: =FV($U$6,AU$9,,-$S18,0) -> 1.4685337 | AY18: =FV($U$6,AW$9,,-$S18,0) -> 1.5125897
A19: =+A18+1 -> 46 | C19: 1 | E19: x | G19: x | I19: x | K19: x | M19: 1 | N19: =N18 -> 2023 | O19: 1 | Q19: 1 | S19: =C19*Q19 -> 1 | U19: =SUM(W19:AY19)+SUM(I52:AK52) -> 47.575416 | W19: =S19 -> 1 | Y19: =FV($U$6,W$9,,-$S19,0) -> 1.03 | AA19: =FV($U$6,Y$9,,-$S19,0) -> 1.0609 | AC19: =FV($U$6,AA$9,,-$S19,0) -> 1.092727 | AE19: =FV($U$6,AC$9,,-$S19,0) -> 1.1255088 | AG19: =FV($U$6,AE$9,,-$S19,0) -> 1.1592741 | AI19: =FV($U$6,AG$9,,-$S19,0) -> 1.1940523 | AK19: =FV($U$6,AI$9,,-$S19,0) -> 1.2298739 | AM19: =FV($U$6,AK$9,,-$S19,0) -> 1.2667701 | AO19: =FV($U$6,AM$9,,-$S19,0) -> 1.3047732 | AQ19: =FV($U$6,AO$9,,-$S19,0) -> 1.3439164 | AS19: =FV($U$6,AQ$9,,-$S19,0) -> 1.3842339 | AU19: =FV($U$6,AS$9,,-$S19,0) -> 1.4257609 | AW19: =FV($U$6,AU$9,,-$S19,0) -> 1.4685337 | AY19: =FV($U$6,AW$9,,-$S19,0) -> 1.5125897
A20: =+A19+1 -> 47 | C20: 1 | E20: x | G20: x | I20: x | K20: x | M20: 1 | N20: =N19 -> 2023 | O20: 1 | Q20: 1 | S20: =C20*Q20 -> 1 | U20: =SUM(W20:AY20)+SUM(I53:AK53) -> 47.575416 | W20: =S20 -> 1 | Y20: =FV($U$6,W$9,,-$S20,0) -> 1.03 | AA20: =FV($U$6,Y$9,,-$S20,0) -> 1.0609 | AC20: =FV($U$6,AA$9,,-$S20,0) -> 1.092727 | AE20: =FV($U$6,AC$9,,-$S20,0) -> 1.1255088 | AG20: =FV($U$6,AE$9,,-$S20,0) -> 1.1592741 | AI20: =FV($U$6,AG$9,,-$S20,0) -> 1.1940523 | AK20: =FV($U$6,AI$9,,-$S20,0) -> 1.2298739 | AM20: =FV($U$6,AK$9,,-$S20,0) -> 1.2667701 | AO20: =FV($U$6,AM$9,,-$S20,0) -> 1.3047732 | AQ20: =FV($U$6,AO$9,,-$S20,0) -> 1.3439164 | AS20: =FV($U$6,AQ$9,,-$S20,0) -> 1.3842339 | AU20: =FV($U$6,AS$9,,-$S20,0) -> 1.4257609 | AW20: =FV($U$6,AU$9,,-$S20,0) -> 1.4685337 | AY20: =FV($U$6,AW$9,,-$S20,0) -> 1.5125897
A21: =+A20+1 -> 48 | C21: 1 | E21: x | G21: x | I21: x | K21: x | M21: 1 | N21: =N20 -> 2023 | O21: 1 | Q21: 1 | S21: =C21*Q21 -> 1 | U21: =SUM(W21:AY21)+SUM(I54:AK54) -> 47.575416 | W21: =S21 -> 1 | Y21: =FV($U$6,W$9,,-$S21,0) -> 1.03 | AA21: =FV($U$6,Y$9,,-$S21,0) -> 1.0609 | AC21: =FV($U$6,AA$9,,-$S21,0) -> 1.092727 | AE21: =FV($U$6,AC$9,,-$S21,0) -> 1.1255088 | AG21: =FV($U$6,AE$9,,-$S21,0) -> 1.1592741 | AI21: =FV($U$6,AG$9,,-$S21,0) -> 1.1940523 | AK21: =FV($U$6,AI$9,,-$S21,0) -> 1.2298739 | AM21: =FV($U$6,AK$9,,-$S21,0) -> 1.2667701 | AO21: =FV($U$6,AM$9,,-$S21,0) -> 1.3047732 | AQ21: =FV($U$6,AO$9,,-$S21,0) -> 1.3439164 | AS21: =FV($U$6,AQ$9,,-$S21,0) -> 1.3842339 | AU21: =FV($U$6,AS$9,,-$S21,0) -> 1.4257609 | AW21: =FV($U$6,AU$9,,-$S21,0) -> 1.4685337 | AY21: =FV($U$6,AW$9,,-$S21,0) -> 1.5125897
A22: =+A21+1 -> 49 | C22: 1 | E22: x | G22: x | I22: x | K22: x | M22: 1 | N22: =N21 -> 2023 | O22: 1 | Q22: 1 | S22: =C22*Q22 -> 1 | U22: =SUM(W22:AY22)+SUM(I55:AK55) -> 47.575416 | W22: =S22 -> 1 | Y22: =FV($U$6,W$9,,-$S22,0) -> 1.03 | AA22: =FV($U$6,Y$9,,-$S22,0) -> 1.0609 | AC22: =FV($U$6,AA$9,,-$S22,0) -> 1.092727 | AE22: =FV($U$6,AC$9,,-$S22,0) -> 1.1255088 | AG22: =FV($U$6,AE$9,,-$S22,0) -> 1.1592741 | AI22: =FV($U$6,AG$9,,-$S22,0) -> 1.1940523 | AK22: =FV($U$6,AI$9,,-$S22,0) -> 1.2298739 | AM22: =FV($U$6,AK$9,,-$S22,0) -> 1.2667701 | AO22: =FV($U$6,AM$9,,-$S22,0) -> 1.3047732 | AQ22: =FV($U$6,AO$9,,-$S22,0) -> 1.3439164 | AS22: =FV($U$6,AQ$9,,-$S22,0) -> 1.3842339 | AU22: =FV($U$6,AS$9,,-$S22,0) -> 1.4257609 | AW22: =FV($U$6,AU$9,,-$S22,0) -> 1.4685337 | AY22: =FV($U$6,AW$9,,-$S22,0) -> 1.5125897
A23: =+A22+1 -> 50 | C23: 1 | E23: x | G23: x | I23: x | K23: x | M23: 1 | N23: =N22 -> 2023 | O23: 1 | Q23: 1 | S23: =C23*Q23 -> 1 | U23: =SUM(W23:AY23)+SUM(I56:AK56) -> 47.575416 | W23: =S23 -> 1 | Y23: =FV($U$6,W$9,,-$S23,0) -> 1.03 | AA23: =FV($U$6,Y$9,,-$S23,0) -> 1.0609 | AC23: =FV($U$6,AA$9,,-$S23,0) -> 1.092727 | AE23: =FV($U$6,AC$9,,-$S23,0) -> 1.1255088 | AG23: =FV($U$6,AE$9,,-$S23,0) -> 1.1592741 | AI23: =FV($U$6,AG$9,,-$S23,0) -> 1.1940523 | AK23: =FV($U$6,AI$9,,-$S23,0) -> 1.2298739 | AM23: =FV($U$6,AK$9,,-$S23,0) -> 1.2667701 | AO23: =FV($U$6,AM$9,,-$S23,0) -> 1.3047732 | AQ23: =FV($U$6,AO$9,,-$S23,0) -> 1.3439164 | AS23: =FV($U$6,AQ$9,,-$S23,0) -> 1.3842339 | AU23: =FV($U$6,AS$9,,-$S23,0) -> 1.4257609 | AW23: =FV($U$6,AU$9,,-$S23,0) -> 1.4685337 | AY23: =FV($U$6,AW$9,,-$S23,0) -> 1.5125897
A24: =+A23+1 -> 51 | C24: 1 | E24: x | G24: x | I24: x | K24: x | M24: 1 | N24: =N23 -> 2023 | O24: 1 | Q24: 1 | S24: =C24*Q24 -> 1 | U24: =SUM(W24:AY24)+SUM(I57:AK57) -> 47.575416 | W24: =S24 -> 1 | Y24: =FV($U$6,W$9,,-$S24,0) -> 1.03 | AA24: =FV($U$6,Y$9,,-$S24,0) -> 1.0609 | AC24: =FV($U$6,AA$9,,-$S24,0) -> 1.092727 | AE24: =FV($U$6,AC$9,,-$S24,0) -> 1.1255088 | AG24: =FV($U$6,AE$9,,-$S24,0) -> 1.1592741 | AI24: =FV($U$6,AG$9,,-$S24,0) -> 1.1940523 | AK24: =FV($U$6,AI$9,,-$S24,0) -> 1.2298739 | AM24: =FV($U$6,AK$9,,-$S24,0) -> 1.2667701 | AO24: =FV($U$6,AM$9,,-$S24,0) -> 1.3047732 | AQ24: =FV($U$6,AO$9,,-$S24,0) -> 1.3439164 | AS24: =FV($U$6,AQ$9,,-$S24,0) -> 1.3842339 | AU24: =FV($U$6,AS$9,,-$S24,0) -> 1.4257609 | AW24: =FV($U$6,AU$9,,-$S24,0) -> 1.4685337 | AY24: =FV($U$6,AW$9,,-$S24,0) -> 1.5125897
A25: =+A24+1 -> 52 | C25: 1 | E25: x | G25: x | I25: x | K25: x | M25: 1 | N25: =N24 -> 2023 | O25: 1 | Q25: 1 | S25: =C25*Q25 -> 1 | U25: =SUM(W25:AY25)+SUM(I58:AK58) -> 47.575416 | W25: =S25 -> 1 | Y25: =FV($U$6,W$9,,-$S25,0) -> 1.03 | AA25: =FV($U$6,Y$9,,-$S25,0) -> 1.0609 | AC25: =FV($U$6,AA$9,,-$S25,0) -> 1.092727 | AE25: =FV($U$6,AC$9,,-$S25,0) -> 1.1255088 | AG25: =FV($U$6,AE$9,,-$S25,0) -> 1.1592741 | AI25: =FV($U$6,AG$9,,-$S25,0) -> 1.1940523 | AK25: =FV($U$6,AI$9,,-$S25,0) -> 1.2298739 | AM25: =FV($U$6,AK$9,,-$S25,0) -> 1.2667701 | AO25: =FV($U$6,AM$9,,-$S25,0) -> 1.3047732 | AQ25: =FV($U$6,AO$9,,-$S25,0) -> 1.3439164 | AS25: =FV($U$6,AQ$9,,-$S25,0) -> 1.3842339 | AU25: =FV($U$6,AS$9,,-$S25,0) -> 1.4257609 | AW25: =FV($U$6,AU$9,,-$S25,0) -> 1.4685337 | AY25: =FV($U$6,AW$9,,-$S25,0) -> 1.5125897
A26: =+A25+1 -> 53 | C26: 1 | E26: x | G26: x | I26: x | K26: x | M26: 1 | N26: =N25 -> 2023 | O26: 1 | Q26: 1 | S26: =C26*Q26 -> 1 | U26: =SUM(W26:AY26)+SUM(I59:AK59) -> 47.575416 | W26: =S26 -> 1 | Y26: =FV($U$6,W$9,,-$S26,0) -> 1.03 | AA26: =FV($U$6,Y$9,,-$S26,0) -> 1.0609 | AC26: =FV($U$6,AA$9,,-$S26,0) -> 1.092727 | AE26: =FV($U$6,AC$9,,-$S26,0) -> 1.1255088 | AG26: =FV($U$6,AE$9,,-$S26,0) -> 1.1592741 | AI26: =FV($U$6,AG$9,,-$S26,0) -> 1.1940523 | AK26: =FV($U$6,AI$9,,-$S26,0) -> 1.2298739 | AM26: =FV($U$6,AK$9,,-$S26,0) -> 1.2667701 | AO26: =FV($U$6,AM$9,,-$S26,0) -> 1.3047732 | AQ26: =FV($U$6,AO$9,,-$S26,0) -> 1.3439164 | AS26: =FV($U$6,AQ$9,,-$S26,0) -> 1.3842339 | AU26: =FV($U$6,AS$9,,-$S26,0) -> 1.4257609 | AW26: =FV($U$6,AU$9,,-$S26,0) -> 1.4685337 | AY26: =FV($U$6,AW$9,,-$S26,0) -> 1.5125897
... A35: =+A34+1 -> 62 | C35: 1 | E35: x | G35: x | I35: x | K35: x | M35: 1 | N35: =N34 -> 2023 | O35: 1 | Q35: 1 | S35: =C35*Q35 -> 1 | U35: =SUM(W35:AY35)+SUM(I68:AK68) -> 47.575416 | W35: =S35 -> 1 | Y35: =FV($U$6,W$9,,-$S35,0) -> 1.03 | AA35: =FV($U$6,Y$9,,-$S35,0) -> 1.0609 | AC35: =FV($U$6,AA$9,,-$S35,0) -> 1.092727 | AE35: =FV($U$6,AC$9,,-$S35,0) -> 1.1255088 | AG35: =FV($U$6,AE$9,,-$S35,0) -> 1.1592741 | AI35: =FV($U$6,AG$9,,-$S35,0) -> 1.1940523 | AK35: =FV($U$6,AI$9,,-$S35,0) -> 1.2298739 | AM35: =FV($U$6,AK$9,,-$S35,0) -> 1.2667701 | AO35: =FV($U$6,AM$9,,-$S35,0) -> 1.3047732 | AQ35: =FV($U$6,AO$9,,-$S35,0) -> 1.3439164 | AS35: =FV($U$6,AQ$9,,-$S35,0) -> 1.3842339 | AU35: =FV($U$6,AS$9,,-$S35,0) -> 1.4257609 | AW35: =FV($U$6,AU$9,,-$S35,0) -> 1.4685337 | AY35: =FV($U$6,AW$9,,-$S35,0) -> 1.5125897
G38: Anticipated Expenditures, By Year | S38: =SUM(S14:S35) -> 22 | U38: =SUM(U14:U35) -> 1046.6591 | W38: =SUM(W14:W36) -> 22 | Y38: =SUM(Y14:Y36) -> 22.66 | AA38: =SUM(AA14:AA36) -> 23.3398 | AC38: =SUM(AC14:AC36) -> 24.039994 | AE38: =SUM(AE14:AE36) -> 24.761194 | AG38: =SUM(AG14:AG36) -> 25.50403 | AI38: =SUM(AI14:AI36) -> 26.269151 | AK38: =SUM(AK14:AK36) -> 27.057225 | AM38: =SUM(AM14:AM36) -> 27.868942 | AO38: =SUM(AO14:AO36) -> 28.70501 | AQ38: =SUM(AQ14:AQ36) -> 29.56616 | AS38: =SUM(AS14:AS36) -> 30.453145 | AU38: =SUM(AU14:AU36) -> 31.36674 | AW38: =SUM(AW14:AW36) -> 32.307742 | AY38: =SUM(AY14:AY36) -> 33.276974
A42: Line Item | I42: 16 | K42: 17 | M42: 18 | O42: 19 | Q42: 20 | S42: =+Q42+1 -> 21 | U42: =+S42+1 -> 22 | W42: =+U42+1 -> 23 | Y42: =+W42+1 -> 24 | AA42: =+Y42+1 -> 25 | AC42: =+AA42+1 -> 26 | AE42: =+AC42+1 -> 27 | AG42: =+AE42+1 -> 28 | AI42: =+AG42+1 -> 29 | AK42: =+AI42+1 -> 30
C43: Quantity | E43: Units | G43: Reserve Component Inventory | I43: =AY10+1 -> 2039 | J43: =AZ10+1 -> 1 | K43: =I43+1 -> 2040 | L43: =J43+1 -> 2 | M43: =K43+1 -> 2041 | N43: =L43+1 -> 3 | O43: =M43+1 -> 2042 | P43: =N43+1 -> 4 | Q43: =O43+1 -> 2043 | S43: =+Q43+1 -> 2044 | T43: =R43+1 -> 1 | U43: =S43+1 -> 2045 | V43: =T43+1 -> 2 | W43: =U43+1 -> 2046 | X43: =V43+1 -> 3 | Y43: =W43+1 -> 2047 | Z43: =X43+1 -> 4 | AA43: =Y43+1 -> 2048 | AC43: =AA43+1 -> 2049 | AE43: =AC43+1 -> 2050 | AG43: =AE43+1 -> 2051 | AI43: =AG43+1 -> 2052 | AK43: =AI43+1 -> 2053
G45: =+G12 -> ELEMENTS
A47: =+A14 -> 41 | C47: =+C14 -> 1 | E47: =+E14 -> x | G47: =+G14 -> x | I47: =FV($U$6,AY$9,,-$S14,0) -> 1.5579674 | K47: =FV($U$6,I$42,,-$S14,0) -> 1.6047064 | M47: =FV($U$6,K$42,,-$S14,0) -> 1.6528476 | O47: =FV($U$6,M$42,,-$S14,0) -> 1.7024331 | Q47: =FV($U$6,O$42,,-$S14,0) -> 1.7535061 | S47: =FV($U$6,Q$42,,-$S14,0) -> 1.8061112 | U47: =FV($U$6,S$42,,-$S14,0) -> 1.8602946 | W47: =FV($U$6,U$42,,-$S14,0) -> 1.9161034 | Y47: =FV($U$6,W$42,,-$S14,0) -> 1.9735865 | AA47: =FV($U$6,Y$42,,-$S14,0) -> 2.0327941 | AC47: =FV($U$6,AA$42,,-$S14,0) -> 2.0937779 | AE47: =FV($U$6,AC$42,,-$S14,0) -> 2.1565913 | AG47: =FV($U$6,AE$42,,-$S14,0) -> 2.221289 | AI47: =FV($U$6,AG$42,,-$S14,0) -> 2.2879277 | AK47: =FV($U$6,AI$42,,-$S14,0) -> 2.3565655
A48: =+A15 -> 42 | C48: =+C15 -> 1 | E48: =+E15 -> x | G48: =+G15 -> x | I48: =FV($U$6,AY$9,,-$S15,0) -> 1.5579674 | K48: =FV($U$6,I$42,,-$S15,0) -> 1.6047064 | M48: =FV($U$6,K$42,,-$S15,0) -> 1.6528476 | O48: =FV($U$6,M$42,,-$S15,0) -> 1.7024331 | Q48: =FV($U$6,O$42,,-$S15,0) -> 1.7535061 | S48: =FV($U$6,Q$42,,-$S15,0) -> 1.8061112 | U48: =FV($U$6,S$42,,-$S15,0) -> 1.8602946 | W48: =FV($U$6,U$42,,-$S15,0) -> 1.9161034 | Y48: =FV($U$6,W$42,,-$S15,0) -> 1.9735865 | AA48: =FV($U$6,Y$42,,-$S15,0) -> 2.0327941 | AC48: =FV($U$6,AA$42,,-$S15,0) -> 2.0937779 | AE48: =FV($U$6,AC$42,,-$S15,0) -> 2.1565913 | AG48: =FV($U$6,AE$42,,-$S15,0) -> 2.221289 | AI48: =FV($U$6,AG$42,,-$S15,0) -> 2.2879277 | AK48: =FV($U$6,AI$42,,-$S15,0) -> 2.3565655
A49: =+A16 -> 43 | C49: =+C16 -> 1 | E49: =+E16 -> x | G49: =+G16 -> x | I49: =FV($U$6,AY$9,,-$S16,0) -> 1.5579674 | K49: =FV($U$6,I$42,,-$S16,0) -> 1.6047064 | M49: =FV($U$6,K$42,,-$S16,0) -> 1.6528476 | O49: =FV($U$6,M$42,,-$S16,0) -> 1.7024331 | Q49: =FV($U$6,O$42,,-$S16,0) -> 1.7535061 | S49: =FV($U$6,Q$42,,-$S16,0) -> 1.8061112 | U49: =FV($U$6,S$42,,-$S16,0) -> 1.8602946 | W49: =FV($U$6,U$42,,-$S16,0) -> 1.9161034 | Y49: =FV($U$6,W$42,,-$S16,0) -> 1.9735865 | AA49: =FV($U$6,Y$42,,-$S16,0) -> 2.0327941 | AC49: =FV($U$6,AA$42,,-$S16,0) -> 2.0937779 | AE49: =FV($U$6,AC$42,,-$S16,0) -> 2.1565913 | AG49: =FV($U$6,AE$42,,-$S16,0) -> 2.221289 | AI49: =FV($U$6,AG$42,,-$S16,0) -> 2.2879277 | AK49: =FV($U$6,AI$42,,-$S16,0) -> 2.3565655
A50: =+A17 -> 44 | C50: =+C17 -> 1 | E50: =+E17 -> x | G50: =+G17 -> x | I50: =FV($U$6,AY$9,,-$S17,0) -> 1.5579674 | K50: =FV($U$6,I$42,,-$S17,0) -> 1.6047064 | M50: =FV($U$6,K$42,,-$S17,0) -> 1.6528476 | O50: =FV($U$6,M$42,,-$S17,0) -> 1.7024331 | Q50: =FV($U$6,O$42,,-$S17,0) -> 1.7535061 | S50: =FV($U$6,Q$42,,-$S17,0) -> 1.8061112 | U50: =FV($U$6,S$42,,-$S17,0) -> 1.8602946 | W50: =FV($U$6,U$42,,-$S17,0) -> 1.9161034 | Y50: =FV($U$6,W$42,,-$S17,0) -> 1.9735865 | AA50: =FV($U$6,Y$42,,-$S17,0) -> 2.0327941 | AC50: =FV($U$6,AA$42,,-$S17,0) -> 2.0937779 | AE50: =FV($U$6,AC$42,,-$S17,0) -> 2.1565913 | AG50: =FV($U$6,AE$42,,-$S17,0) -> 2.221289 | AI50: =FV($U$6,AG$42,,-$S17,0) -> 2.2879277 | AK50: =FV($U$6,AI$42,,-$S17,0) -> 2.3565655
A51: =+A18 -> 45 | C51: =+C18 -> 1 | E51: =+E18 -> x | G51: =+G18 -> x | I51: =FV($U$6,AY$9,,-$S18,0) -> 1.5579674 | K51: =FV($U$6,I$42,,-$S18,0) -> 1.6047064 | M51: =FV($U$6,K$42,,-$S18,0) -> 1.6528476 | O51: =FV($U$6,M$42,,-$S18,0) -> 1.7024331 | Q51: =FV($U$6,O$42,,-$S18,0) -> 1.7535061 | S51: =FV($U$6,Q$42,,-$S18,0) -> 1.8061112 | U51: =FV($U$6,S$42,,-$S18,0) -> 1.8602946 | W51: =FV($U$6,U$42,,-$S18,0) -> 1.9161034 | Y51: =FV($U$6,W$42,,-$S18,0) -> 1.9735865 | AA51: =FV($U$6,Y$42,,-$S18,0) -> 2.0327941 | AC51: =FV($U$6,AA$42,,-$S18,0) -> 2.0937779 | AE51: =FV($U$6,AC$42,,-$S18,0) -> 2.1565913 | AG51: =FV($U$6,AE$42,,-$S18,0) -> 2.221289 | AI51: =FV($U$6,AG$42,,-$S18,0) -> 2.2879277 | AK51: =FV($U$6,AI$42,,-$S18,0) -> 2.3565655
A52: =+A19 -> 46 | C52: =+C19 -> 1 | E52: =+E19 -> x | G52: =+G19 -> x | I52: =FV($U$6,AY$9,,-$S19,0) -> 1.5579674 | K52: =FV($U$6,I$42,,-$S19,0) -> 1.6047064 | M52: =FV($U$6,K$42,,-$S19,0) -> 1.6528476 | O52: =FV($U$6,M$42,,-$S19,0) -> 1.7024331 | Q52: =FV($U$6,O$42,,-$S19,0) -> 1.7535061 | S52: =FV($U$6,Q$42,,-$S19,0) -> 1.8061112 | U52: =FV($U$6,S$42,,-$S19,0) -> 1.8602946 | W52: =FV($U$6,U$42,,-$S19,0) -> 1.9161034 | Y52: =FV($U$6,W$42,,-$S19,0) -> 1.9735865 | AA52: =FV($U$6,Y$42,,-$S19,0) -> 2.0327941 | AC52: =FV($U$6,AA$42,,-$S19,0) -> 2.0937779 | AE52: =FV($U$6,AC$42,,-$S19,0) -> 2.1565913 | AG52: =FV($U$6,AE$42,,-$S19,0) -> 2.221289 | AI52: =FV($U$6,AG$42,,-$S19,0) -> 2.2879277 | AK52: =FV($U$6,AI$42,,-$S19,0) -> 2.3565655
A53: =+A20 -> 47 | C53: =+C20 -> 1 | E53: =+E20 -> x | G53: =+G20 -> x | I53: =FV($U$6,AY$9,,-$S20,0) -> 1.5579674 | K53: =FV($U$6,I$42,,-$S20,0) -> 1.6047064 | M53: =FV($U$6,K$42,,-$S20,0) -> 1.6528476 | O53: =FV($U$6,M$42,,-$S20,0) -> 1.7024331 | Q53: =FV($U$6,O$42,,-$S20,0) -> 1.7535061 | S53: =FV($U$6,Q$42,,-$S20,0) -> 1.8061112 | U53: =FV($U$6,S$42,,-$S20,0) -> 1.8602946 | W53: =FV($U$6,U$42,,-$S20,0) -> 1.9161034 | Y53: =FV($U$6,W$42,,-$S20,0) -> 1.9735865 | AA53: =FV($U$6,Y$42,,-$S20,0) -> 2.0327941 | AC53: =FV($U$6,AA$42,,-$S20,0) -> 2.0937779 | AE53: =FV($U$6,AC$42,,-$S20,0) -> 2.1565913 | AG53: =FV($U$6,AE$42,,-$S20,0) -> 2.221289 | AI53: =FV($U$6,AG$42,,-$S20,0) -> 2.2879277 | AK53: =FV($U$6,AI$42,,-$S20,0) -> 2.3565655
A54: =+A21 -> 48 | C54: =+C21 -> 1 | E54: =+E21 -> x | G54: =+G21 -> x | I54: =FV($U$6,AY$9,,-$S21,0) -> 1.5579674 | K54: =FV($U$6,I$42,,-$S21,0) -> 1.6047064 | M54: =FV($U$6,K$42,,-$S21,0) -> 1.6528476 | O54: =FV($U$6,M$42,,-$S21,0) -> 1.7024331 | Q54: =FV($U$6,O$42,,-$S21,0) -> 1.7535061 | S54: =FV($U$6,Q$42,,-$S21,0) -> 1.8061112 | U54: =FV($U$6,S$42,,-$S21,0) -> 1.8602946 | W54: =FV($U$6,U$42,,-$S21,0) -> 1.9161034 | Y54: =FV($U$6,W$42,,-$S21,0) -> 1.9735865 | AA54: =FV($U$6,Y$42,,-$S21,0) -> 2.0327941 | AC54: =FV($U$6,AA$42,,-$S21,0) -> 2.0937779 | AE54: =FV($U$6,AC$42,,-$S21,0) -> 2.1565913 | AG54: =FV($U$6,AE$42,,-$S21,0) -> 2.221289 | AI54: =FV($U$6,AG$42,,-$S21,0) -> 2.2879277 | AK54: =FV($U$6,AI$42,,-$S21,0) -> 2.3565655
A55: =+A22 -> 49 | C55: =+C22 -> 1 | E55: =+E22 -> x | G55: =+G22 -> x | I55: =FV($U$6,AY$9,,-$S22,0) -> 1.5579674 | K55: =FV($U$6,I$42,,-$S22,0) -> 1.6047064 | M55: =FV($U$6,K$42,,-$S22,0) -> 1.6528476 | O55: =FV($U$6,M$42,,-$S22,0) -> 1.7024331 | Q55: =FV($U$6,O$42,,-$S22,0) -> 1.7535061 | S55: =FV($U$6,Q$42,,-$S22,0) -> 1.8061112 | U55: =FV($U$6,S$42,,-$S22,0) -> 1.8602946 | W55: =FV($U$6,U$42,,-$S22,0) -> 1.9161034 | Y55: =FV($U$6,W$42,,-$S22,0) -> 1.9735865 | AA55: =FV($U$6,Y$42,,-$S22,0) -> 2.0327941 | AC55: =FV($U$6,AA$42,,-$S22,0) -> 2.0937779 | AE55: =FV($U$6,AC$42,,-$S22,0) -> 2.1565913 | AG55: =FV($U$6,AE$42,,-$S22,0) -> 2.221289 | AI55: =FV($U$6,AG$42,,-$S22,0) -> 2.2879277 | AK55: =FV($U$6,AI$42,,-$S22,0) -> 2.3565655
A56: =+A23 -> 50 | C56: =+C23 -> 1 | E56: =+E23 -> x | G56: =+G23 -> x | I56: =FV($U$6,AY$9,,-$S23,0) -> 1.5579674 | K56: =FV($U$6,I$42,,-$S23,0) -> 1.6047064 | M56: =FV($U$6,K$42,,-$S23,0) -> 1.6528476 | O56: =FV($U$6,M$42,,-$S23,0) -> 1.7024331 | Q56: =FV($U$6,O$42,,-$S23,0) -> 1.7535061 | S56: =FV($U$6,Q$42,,-$S23,0) -> 1.8061112 | U56: =FV($U$6,S$42,,-$S23,0) -> 1.8602946 | W56: =FV($U$6,U$42,,-$S23,0) -> 1.9161034 | Y56: =FV($U$6,W$42,,-$S23,0) -> 1.9735865 | AA56: =FV($U$6,Y$42,,-$S23,0) -> 2.0327941 | AC56: =FV($U$6,AA$42,,-$S23,0) -> 2.0937779 | AE56: =FV($U$6,AC$42,,-$S23,0) -> 2.1565913 | AG56: =FV($U$6,AE$42,,-$S23,0) -> 2.221289 | AI56: =FV($U$6,AG$42,,-$S23,0) -> 2.2879277 | AK56: =FV($U$6,AI$42,,-$S23,0) -> 2.3565655
A57: =+A24 -> 51 | C57: =+C24 -> 1 | E57: =+E24 -> x | G57: =+G24 -> x | I57: =FV($U$6,AY$9,,-$S24,0) -> 1.5579674 | K57: =FV($U$6,I$42,,-$S24,0) -> 1.6047064 | M57: =FV($U$6,K$42,,-$S24,0) -> 1.6528476 | O57: =FV($U$6,M$42,,-$S24,0) -> 1.7024331 | Q57: =FV($U$6,O$42,,-$S24,0) -> 1.7535061 | S57: =FV($U$6,Q$42,,-$S24,0) -> 1.8061112 | U57: =FV($U$6,S$42,,-$S24,0) -> 1.8602946 | W57: =FV($U$6,U$42,,-$S24,0) -> 1.9161034 | Y57: =FV($U$6,W$42,,-$S24,0) -> 1.9735865 | AA57: =FV($U$6,Y$42,,-$S24,0) -> 2.0327941 | AC57: =FV($U$6,AA$42,,-$S24,0) -> 2.0937779 | AE57: =FV($U$6,AC$42,,-$S24,0) -> 2.1565913 | AG57: =FV($U$6,AE$42,,-$S24,0) -> 2.221289 | AI57: =FV($U$6,AG$42,,-$S24,0) -> 2.2879277 | AK57: =FV($U$6,AI$42,,-$S24,0) -> 2.3565655
A58: =+A25 -> 52 | C58: =+C25 -> 1 | E58: =+E25 -> x | G58: =+G25 -> x | I58: =FV($U$6,AY$9,,-$S25,0) -> 1.5579674 | K58: =FV($U$6,I$42,,-$S25,0) -> 1.6047064 | M58: =FV($U$6,K$42,,-$S25,0) -> 1.6528476 | O58: =FV($U$6,M$42,,-$S25,0) -> 1.7024331 | Q58: =FV($U$6,O$42,,-$S25,0) -> 1.7535061 | S58: =FV($U$6,Q$42,,-$S25,0) -> 1.8061112 | U58: =FV($U$6,S$42,,-$S25,0) -> 1.8602946 | W58: =FV($U$6,U$42,,-$S25,0) -> 1.9161034 | Y58: =FV($U$6,W$42,,-$S25,0) -> 1.9735865 | AA58: =FV($U$6,Y$42,,-$S25,0) -> 2.0327941 | AC58: =FV($U$6,AA$42,,-$S25,0) -> 2.0937779 | AE58: =FV($U$6,AC$42,,-$S25,0) -> 2.1565913 | AG58: =FV($U$6,AE$42,,-$S25,0) -> 2.221289 | AI58: =FV($U$6,AG$42,,-$S25,0) -> 2.2879277 | AK58: =FV($U$6,AI$42,,-$S25,0) -> 2.3565655
... A68: =+A35 -> 62 | C68: =+C35 -> 1 | E68: =+E35 -> x | G68: =+G35 -> x | I68: =FV($U$6,AY$9,,-$S35,0) -> 1.5579674 | K68: =FV($U$6,I$42,,-$S35,0) -> 1.6047064 | M68: =FV($U$6,K$42,,-$S35,0) -> 1.6528476 | O68: =FV($U$6,M$42,,-$S35,0) -> 1.7024331 | Q68: =FV($U$6,O$42,,-$S35,0) -> 1.7535061 | S68: =FV($U$6,Q$42,,-$S35,0) -> 1.8061112 | U68: =FV($U$6,S$42,,-$S35,0) -> 1.8602946 | W68: =FV($U$6,U$42,,-$S35,0) -> 1.9161034 | Y68: =FV($U$6,W$42,,-$S35,0) -> 1.9735865 | AA68: =FV($U$6,Y$42,,-$S35,0) -> 2.0327941 | AC68: =FV($U$6,AA$42,,-$S35,0) -> 2.0937779 | AE68: =FV($U$6,AC$42,,-$S35,0) -> 2.1565913 | AG68: =FV($U$6,AE$42,,-$S35,0) -> 2.221289 | AI68: =FV($U$6,AG$42,,-$S35,0) -> 2.2879277 | AK68: =FV($U$6,AI$42,,-$S35,0) -> 2.3565655
G71: =+G38 -> Anticipated Expenditures, By Year | I71: =SUM(I47:I69) -> 34.275283 | K71: =SUM(K47:K69) -> 35.303542 | M71: =SUM(M47:M69) -> 36.362648 | O71: =SUM(O47:O69) -> 37.453527 | Q71: =SUM(Q47:Q69) -> 38.577133 | S71: =SUM(S47:S69) -> 39.734447 | U71: =SUM(U47:U69) -> 40.926481 | W71: =SUM(W47:W69) -> 42.154275 | Y71: =SUM(Y47:Y69) -> 43.418903 | AA71: =SUM(AA47:AA69) -> 44.72147 | AC71: =SUM(AC47:AC69) -> 46.063114 | AE71: =SUM(AE47:AE69) -> 47.445008 | AG71: =SUM(AG47:AG69) -> 48.868358 | AI71: =SUM(AI47:AI69) -> 50.334409 | AK71: =SUM(AK47:AK69) -> 51.844441

Sheet Maintain (PRN) 2
G3: Exhibit B
G5: RESERVE EXPENDITURES | U5: Explanatory Notes:
G6: for | T6: 1) | U6: =+'Roofs 1'!V3 -> 0.03 | V6: is the estimated future Inflation Rate for estimating Future Replacement Costs.
G7: =+'Roofs 1'!H5 -> Association | T7: 2) | U7: Fiscal Year is beginning January 1 and ending December 31.
A9: Line Item | C9: Estimated | I9: Estimated Year Last Replaced | K9: Life Analysis, Years | O9: Estimated Year of 1st Replacement | Q9: =+'Roofs 1'!R6 -> 2024 Unit Cost | S9: =+'Roofs 1'!T6 -> 2024 Cost of Replacement | U9: Total Future Cost of Replacement | W9: 1 | Y9: 2 | AA9: 3 | AC9: 4 | AE9: 5 | AG9: 6 | AI9: 7 | AK9: 8 | AM9: 9 | AO9: 10 | AQ9: 11 | AS9: 12 | AU9: 13 | AW9: 14 | AY9: 15
C10: Quantity | E10: Units | G10: Reserve Component Inventory | K10: Useful | M10: Remaining | W10: =+'Roofs 1'!X7 -> 2024 | Y10: =W10+1 -> 2025 | Z10: =X10+1 -> 1 | AA10: =Y10+1 -> 2026 | AB10: =Z10+1 -> 2 | AC10: =AA10+1 -> 2027 | AD10: =AB10+1 -> 3 | AE10: =AC10+1 -> 2028 | AF10: =AD10+1 -> 4 | ... AY10: =AW10+1 -> 2038
G12: ELEMENTS
A14: ='Roofs 1'!B50+1 -> 41 | C14: 1 | E14: x | G14: x | I14: x | K14: x | M14: 1 | N14: ='Roofs 1'!P4 -> 2023 | O14: 1 | Q14: 1 | S14: =C14*Q14 -> 1 | U14: =SUM(W14:AY14)+SUM(I47:AK47) -> 47.575416 | W14: =S14 -> 1 | Y14: =FV($U$6,W$9,,-$S14,0) -> 1.03 | AA14: =FV($U$6,Y$9,,-$S14,0) -> 1.0609 | AC14: =FV($U$6,AA$9,,-$S14,0) -> 1.092727 | AE14: =FV($U$6,AC$9,,-$S14,0) -> 1.1255088 | AG14: =FV($U$6,AE$9,,-$S14,0) -> 1.1592741 | AI14: =FV($U$6,AG$9,,-$S14,0) -> 1.1940523 | AK14: =FV($U$6,AI$9,,-$S14,0) -> 1.2298739 | AM14: =FV($U$6,AK$9,,-$S14,0) -> 1.2667701 | AO14: =FV($U$6,AM$9,,-$S14,0) -> 1.3047732 | AQ14: =FV($U$6,AO$9,,-$S14,0) -> 1.3439164 | AS14: =FV($U$6,AQ$9,,-$S14,0) -> 1.3842339 | AU14: =FV($U$6,AS$9,,-$S14,0) -> 1.4257609 | AW14: =FV($U$6,AU$9,,-$S14,0) -> 1.4685337 | AY14: =FV($U$6,AW$9,,-$S14,0) -> 1.5125897
A15: =+A14+1 -> 42 | C15: 1 | E15: x | G15: x | I15: x | K15: x | M15: 1 | N15: =N14 -> 2023 | O15: 1 | Q15: 1 | S15: =C15*Q15 -> 1 | U15: =SUM(W15:AY15)+SUM(I48:AK48) -> 47.575416 | W15: =S15 -> 1 | Y15: =FV($U$6,W$9,,-$S15,0) -> 1.03 | AA15: =FV($U$6,Y$9,,-$S15,0) -> 1.0609 | AC15: =FV($U$6,AA$9,,-$S15,0) -> 1.092727 | AE15: =FV($U$6,AC$9,,-$S15,0) -> 1.1255088 | AG15: =FV($U$6,AE$9,,-$S15,0) -> 1.1592741 | AI15: =FV($U$6,AG$9,,-$S15,0) -> 1.1940523 | AK15: =FV($U$6,AI$9,,-$S15,0) -> 1.2298739 | AM15: =FV($U$6,AK$9,,-$S15,0) -> 1.2667701 | AO15: =FV($U$6,AM$9,,-$S15,0) -> 1.3047732 | AQ15: =FV($U$6,AO$9,,-$S15,0) -> 1.3439164 | AS15: =FV($U$6,AQ$9,,-$S15,0) -> 1.3842339 | AU15: =FV($U$6,AS$9,,-$S15,0) -> 1.4257609 | AW15: =FV($U$6,AU$9,,-$S15,0) -> 1.4685337 | AY15: =FV($U$6,AW$9,,-$S15,0) -> 1.5125897
A16: =+A15+1 -> 43 | C16: 1 | E16: x | G16: x | I16: x | K16: x | M16: 1 | N16: =N15 -> 2023 | O16: 1 | Q16: 1 | S16: =C16*Q16 -> 1 | U16: =SUM(W16:AY16)+SUM(I49:AK49) -> 47.575416 | W16: =S16 -> 1 | Y16: =FV($U$6,W$9,,-$S16,0) -> 1.03 | AA16: =FV($U$6,Y$9,,-$S16,0) -> 1.0609 | AC16: =FV($U$6,AA$9,,-$S16,0) -> 1.092727 | AE16: =FV($U$6,AC$9,,-$S16,0) -> 1.1255088 | AG16: =FV($U$6,AE$9,,-$S16,0) -> 1.1592741 | AI16: =FV($U$6,AG$9,,-$S16,0) -> 1.1940523 | AK16: =FV($U$6,AI$9,,-$S16,0) -> 1.2298739 | AM16: =FV($U$6,AK$9,,-$S16,0) -> 1.2667701 | AO16: =FV($U$6,AM$9,,-$S16,0) -> 1.3047732 | AQ16: =FV($U$6,AO$9,,-$S16,0) -> 1.3439164 | AS16: =FV($U$6,AQ$9,,-$S16,0) -> 1.3842339 | AU16: =FV($U$6,AS$9,,-$S16,0) -> 1.4257609 | AW16: =FV($U$6,AU$9,,-$S16,0) -> 1.4685337 | AY16: =FV($U$6,AW$9,,-$S16,0) -> 1.5125897
A17: =+A16+1 -> 44 | C17: 1 | E17: x | G17: x | I17: x | K17: x | M17: 1 | N17: =N16 -> 2023 | O17: 1 | Q17: 1 | S17: =C17*Q17 -> 1 | U17: =SUM(W17:AY17)+SUM(I50:AK50) -> 47.575416 | W17: =S17 -> 1 | Y17: =FV($U$6,W$9,,-$S17,0) -> 1.03 | AA17: =FV($U$6,Y$9,,-$S17,0) -> 1.0609 | AC17: =FV($U$6,AA$9,,-$S17,0) -> 1.092727 | AE17: =FV($U$6,AC$9,,-$S17,0) -> 1.1255088 | AG17: =FV($U$6,AE$9,,-$S17,0) -> 1.1592741 | AI17: =FV($U$6,AG$9,,-$S17,0) -> 1.1940523 | AK17: =FV($U$6,AI$9,,-$S17,0) -> 1.2298739 | AM17: =FV($U$6,AK$9,,-$S17,0) -> 1.2667701 | AO17: =FV($U$6,AM$9,,-$S17,0) -> 1.3047732 | AQ17: =FV($U$6,AO$9,,-$S17,0) -> 1.3439164 | AS17: =FV($U$6,AQ$9,,-$S17,0) -> 1.3842339 | AU17: =FV($U$6,AS$9,,-$S17,0) -> 1.4257609 | AW17: =FV($U$6,AU$9,,-$S17,0) -> 1.4685337 | AY17: =FV($U$6,AW$9,,-$S17,0) -> 1.5125897
A18: =+A17+1 -> 45 | C18: 1 | E18: x | G18: x | I18: x | K18: x | M18: 1 | N18: =N17 -> 2023 | O18: 1 | Q18: 1 | S18: =C18*Q18 -> 1 | U18: =SUM(W18:AY18)+SUM(I51:AK51) -> 47.575416 | W18: =S18 -> 1 | Y18: =FV($U$6,W$9,,-$S18,0) -> 1.03 | AA18: =FV($U$6,Y$9,,-$S18,0) -> 1.0609 | AC18: =FV($U$6,AA$9,,-$S18,0) -> 1.092727 | AE18: =FV($U$6,AC$9,,-$S18,0) -> 1.1255088 | AG18: =FV($U$6,AE$9,,-$S18,0) -> 1.1592741 | AI18: =FV($U$6,AG$9,,-$S18,0) -> 1.1940523 | AK18: =FV($U$6,AI$9,,-$S18,0) -> 1.2298739 | AM18: =FV($U$6,AK$9,,-$S18,0) -> 1.2667701 | AO18: =FV($U$6,AM$9,,-$S18,0) -> 1.3047732 | AQ18: =FV($U$6,AO$9,,-$S18,0) -> 1.3439164 | AS18: =FV($U$6,AQ$9,,-$S18,0) -> 1.3842339 | AU18: =FV($U$6,AS$9,,-$S18,0) -> 1.4257609 | AW18: =FV($U$6,AU$9,,-$S18,0) -> 1.4685337 | AY18: =FV($U$6,AW$9,,-$S18,0) -> 1.5125897
A19: =+A18+1 -> 46 | C19: 1 | E19: x | G19: x | I19: x | K19: x | M19: 1 | N19: =N18 -> 2023 | O19: 1 | Q19: 1 | S19: =C19*Q19 -> 1 | U19: =SUM(W19:AY19)+SUM(I52:AK52) -> 47.575416 | W19: =S19 -> 1 | Y19: =FV($U$6,W$9,,-$S19,0) -> 1.03 | AA19: =FV($U$6,Y$9,,-$S19,0) -> 1.0609 | AC19: =FV($U$6,AA$9,,-$S19,0) -> 1.092727 | AE19: =FV($U$6,AC$9,,-$S19,0) -> 1.1255088 | AG19: =FV($U$6,AE$9,,-$S19,0) -> 1.1592741 | AI19: =FV($U$6,AG$9,,-$S19,0) -> 1.1940523 | AK19: =FV($U$6,AI$9,,-$S19,0) -> 1.2298739 | AM19: =FV($U$6,AK$9,,-$S19,0) -> 1.2667701 | AO19: =FV($U$6,AM$9,,-$S19,0) -> 1.3047732 | AQ19: =FV($U$6,AO$9,,-$S19,0) -> 1.3439164 | AS19: =FV($U$6,AQ$9,,-$S19,0) -> 1.3842339 | AU19: =FV($U$6,AS$9,,-$S19,0) -> 1.4257609 | AW19: =FV($U$6,AU$9,,-$S19,0) -> 1.4685337 | AY19: =FV($U$6,AW$9,,-$S19,0) -> 1.5125897
